[2020-07-07 14:38:19 -0700] [17808] [CRITICAL] WORKER TIMEOUT (pid:17813)
[2020-07-07 17:15:29 -0700] [19129] [ERROR] Exception in worker process
Traceback (most recent call last):
  File "/Users/dankmank/anaconda3/lib/python3.7/site-packages/sqlalchemy/engine/base.py", line 2345, in _wrap_pool_connect
    return fn()
  File "/Users/dankmank/anaconda3/lib/python3.7/site-packages/sqlalchemy/pool/base.py", line 364, in connect
    return _ConnectionFairy._checkout(self)
  File "/Users/dankmank/anaconda3/lib/python3.7/site-packages/sqlalchemy/pool/base.py", line 778, in _checkout
    fairy = _ConnectionRecord.checkout(pool)
  File "/Users/dankmank/anaconda3/lib/python3.7/site-packages/sqlalchemy/pool/base.py", line 495, in checkout
    rec = pool._do_get()
  File "/Users/dankmank/anaconda3/lib/python3.7/site-packages/sqlalchemy/pool/impl.py", line 140, in _do_get
    self._dec_overflow()
  File "/Users/dankmank/anaconda3/lib/python3.7/site-packages/sqlalchemy/util/langhelpers.py", line 69, in __exit__
    exc_value, with_traceback=exc_tb,
  File "/Users/dankmank/anaconda3/lib/python3.7/site-packages/sqlalchemy/util/compat.py", line 178, in raise_
    raise exception
  File "/Users/dankmank/anaconda3/lib/python3.7/site-packages/sqlalchemy/pool/impl.py", line 137, in _do_get
    return self._create_connection()
  File "/Users/dankmank/anaconda3/lib/python3.7/site-packages/sqlalchemy/pool/base.py", line 309, in _create_connection
    return _ConnectionRecord(self)
  File "/Users/dankmank/anaconda3/lib/python3.7/site-packages/sqlalchemy/pool/base.py", line 440, in __init__
    self.__connect(first_connect_check=True)
  File "/Users/dankmank/anaconda3/lib/python3.7/site-packages/sqlalchemy/pool/base.py", line 661, in __connect
    pool.logger.debug("Error on connect(): %s", e)
  File "/Users/dankmank/anaconda3/lib/python3.7/site-packages/sqlalchemy/util/langhelpers.py", line 69, in __exit__
    exc_value, with_traceback=exc_tb,
  File "/Users/dankmank/anaconda3/lib/python3.7/site-packages/sqlalchemy/util/compat.py", line 178, in raise_
    raise exception
  File "/Users/dankmank/anaconda3/lib/python3.7/site-packages/sqlalchemy/pool/base.py", line 656, in __connect
    connection = pool._invoke_creator(self)
  File "/Users/dankmank/anaconda3/lib/python3.7/site-packages/sqlalchemy/engine/strategies.py", line 114, in connect
    return dialect.connect(*cargs, **cparams)
  File "/Users/dankmank/anaconda3/lib/python3.7/site-packages/sqlalchemy/engine/default.py", line 490, in connect
    return self.dbapi.connect(*cargs, **cparams)
  File "/Users/dankmank/anaconda3/lib/python3.7/site-packages/psycopg2/__init__.py", line 127, in connect
    conn = _connect(dsn, connection_factory=connection_factory, **kwasync)
psycopg2.OperationalError: FATAL:  too many connections for role "kdscstklqmukmb"


The above exception was the direct cause of the following exception:

Traceback (most recent call last):
  File "/Users/dankmank/anaconda3/lib/python3.7/site-packages/gunicorn/arbiter.py", line 583, in spawn_worker
    worker.init_process()
  File "/Users/dankmank/anaconda3/lib/python3.7/site-packages/gunicorn/workers/base.py", line 129, in init_process
    self.load_wsgi()
  File "/Users/dankmank/anaconda3/lib/python3.7/site-packages/gunicorn/workers/base.py", line 138, in load_wsgi
    self.wsgi = self.app.wsgi()
  File "/Users/dankmank/anaconda3/lib/python3.7/site-packages/gunicorn/app/base.py", line 67, in wsgi
    self.callable = self.load()
  File "/Users/dankmank/anaconda3/lib/python3.7/site-packages/psiturk/experiment_server.py", line 48, in load
    return util.import_app("psiturk.experiment:app")
  File "/Users/dankmank/anaconda3/lib/python3.7/site-packages/gunicorn/util.py", line 350, in import_app
    __import__(module)
  File "/Users/dankmank/anaconda3/lib/python3.7/site-packages/psiturk/experiment.py", line 89, in <module>
    init_db()
  File "/Users/dankmank/anaconda3/lib/python3.7/site-packages/psiturk/db.py", line 37, in init_db
    Base.metadata.create_all(bind=engine)
  File "/Users/dankmank/anaconda3/lib/python3.7/site-packages/sqlalchemy/sql/schema.py", line 4465, in create_all
    ddl.SchemaGenerator, self, checkfirst=checkfirst, tables=tables
  File "/Users/dankmank/anaconda3/lib/python3.7/site-packages/sqlalchemy/engine/base.py", line 2103, in _run_visitor
    with self._optional_conn_ctx_manager(connection) as conn:
  File "/Users/dankmank/anaconda3/lib/python3.7/contextlib.py", line 112, in __enter__
    return next(self.gen)
  File "/Users/dankmank/anaconda3/lib/python3.7/site-packages/sqlalchemy/engine/base.py", line 2095, in _optional_conn_ctx_manager
    with self._contextual_connect() as conn:
  File "/Users/dankmank/anaconda3/lib/python3.7/site-packages/sqlalchemy/engine/base.py", line 2311, in _contextual_connect
    self._wrap_pool_connect(self.pool.connect, None),
  File "/Users/dankmank/anaconda3/lib/python3.7/site-packages/sqlalchemy/engine/base.py", line 2349, in _wrap_pool_connect
    e, dialect, self
  File "/Users/dankmank/anaconda3/lib/python3.7/site-packages/sqlalchemy/engine/base.py", line 1591, in _handle_dbapi_exception_noconnection
    sqlalchemy_exception, with_traceback=exc_info[2], from_=e
  File "/Users/dankmank/anaconda3/lib/python3.7/site-packages/sqlalchemy/util/compat.py", line 178, in raise_
    raise exception
  File "/Users/dankmank/anaconda3/lib/python3.7/site-packages/sqlalchemy/engine/base.py", line 2345, in _wrap_pool_connect
    return fn()
  File "/Users/dankmank/anaconda3/lib/python3.7/site-packages/sqlalchemy/pool/base.py", line 364, in connect
    return _ConnectionFairy._checkout(self)
  File "/Users/dankmank/anaconda3/lib/python3.7/site-packages/sqlalchemy/pool/base.py", line 778, in _checkout
    fairy = _ConnectionRecord.checkout(pool)
  File "/Users/dankmank/anaconda3/lib/python3.7/site-packages/sqlalchemy/pool/base.py", line 495, in checkout
    rec = pool._do_get()
  File "/Users/dankmank/anaconda3/lib/python3.7/site-packages/sqlalchemy/pool/impl.py", line 140, in _do_get
    self._dec_overflow()
  File "/Users/dankmank/anaconda3/lib/python3.7/site-packages/sqlalchemy/util/langhelpers.py", line 69, in __exit__
    exc_value, with_traceback=exc_tb,
  File "/Users/dankmank/anaconda3/lib/python3.7/site-packages/sqlalchemy/util/compat.py", line 178, in raise_
    raise exception
  File "/Users/dankmank/anaconda3/lib/python3.7/site-packages/sqlalchemy/pool/impl.py", line 137, in _do_get
    return self._create_connection()
  File "/Users/dankmank/anaconda3/lib/python3.7/site-packages/sqlalchemy/pool/base.py", line 309, in _create_connection
    return _ConnectionRecord(self)
  File "/Users/dankmank/anaconda3/lib/python3.7/site-packages/sqlalchemy/pool/base.py", line 440, in __init__
    self.__connect(first_connect_check=True)
  File "/Users/dankmank/anaconda3/lib/python3.7/site-packages/sqlalchemy/pool/base.py", line 661, in __connect
    pool.logger.debug("Error on connect(): %s", e)
  File "/Users/dankmank/anaconda3/lib/python3.7/site-packages/sqlalchemy/util/langhelpers.py", line 69, in __exit__
    exc_value, with_traceback=exc_tb,
  File "/Users/dankmank/anaconda3/lib/python3.7/site-packages/sqlalchemy/util/compat.py", line 178, in raise_
    raise exception
  File "/Users/dankmank/anaconda3/lib/python3.7/site-packages/sqlalchemy/pool/base.py", line 656, in __connect
    connection = pool._invoke_creator(self)
  File "/Users/dankmank/anaconda3/lib/python3.7/site-packages/sqlalchemy/engine/strategies.py", line 114, in connect
    return dialect.connect(*cargs, **cparams)
  File "/Users/dankmank/anaconda3/lib/python3.7/site-packages/sqlalchemy/engine/default.py", line 490, in connect
    return self.dbapi.connect(*cargs, **cparams)
  File "/Users/dankmank/anaconda3/lib/python3.7/site-packages/psycopg2/__init__.py", line 127, in connect
    conn = _connect(dsn, connection_factory=connection_factory, **kwasync)
sqlalchemy.exc.OperationalError: (psycopg2.OperationalError) FATAL:  too many connections for role "kdscstklqmukmb"

(Background on this error at: http://sqlalche.me/e/e3q8)
[2020-07-07 17:15:29 -0700] [19130] [ERROR] Exception in worker process
Traceback (most recent call last):
  File "/Users/dankmank/anaconda3/lib/python3.7/site-packages/sqlalchemy/engine/base.py", line 2345, in _wrap_pool_connect
    return fn()
  File "/Users/dankmank/anaconda3/lib/python3.7/site-packages/sqlalchemy/pool/base.py", line 364, in connect
    return _ConnectionFairy._checkout(self)
  File "/Users/dankmank/anaconda3/lib/python3.7/site-packages/sqlalchemy/pool/base.py", line 778, in _checkout
    fairy = _ConnectionRecord.checkout(pool)
  File "/Users/dankmank/anaconda3/lib/python3.7/site-packages/sqlalchemy/pool/base.py", line 495, in checkout
    rec = pool._do_get()
  File "/Users/dankmank/anaconda3/lib/python3.7/site-packages/sqlalchemy/pool/impl.py", line 140, in _do_get
    self._dec_overflow()
  File "/Users/dankmank/anaconda3/lib/python3.7/site-packages/sqlalchemy/util/langhelpers.py", line 69, in __exit__
    exc_value, with_traceback=exc_tb,
  File "/Users/dankmank/anaconda3/lib/python3.7/site-packages/sqlalchemy/util/compat.py", line 178, in raise_
    raise exception
  File "/Users/dankmank/anaconda3/lib/python3.7/site-packages/sqlalchemy/pool/impl.py", line 137, in _do_get
    return self._create_connection()
  File "/Users/dankmank/anaconda3/lib/python3.7/site-packages/sqlalchemy/pool/base.py", line 309, in _create_connection
    return _ConnectionRecord(self)
  File "/Users/dankmank/anaconda3/lib/python3.7/site-packages/sqlalchemy/pool/base.py", line 440, in __init__
    self.__connect(first_connect_check=True)
  File "/Users/dankmank/anaconda3/lib/python3.7/site-packages/sqlalchemy/pool/base.py", line 661, in __connect
    pool.logger.debug("Error on connect(): %s", e)
  File "/Users/dankmank/anaconda3/lib/python3.7/site-packages/sqlalchemy/util/langhelpers.py", line 69, in __exit__
    exc_value, with_traceback=exc_tb,
  File "/Users/dankmank/anaconda3/lib/python3.7/site-packages/sqlalchemy/util/compat.py", line 178, in raise_
    raise exception
  File "/Users/dankmank/anaconda3/lib/python3.7/site-packages/sqlalchemy/pool/base.py", line 656, in __connect
    connection = pool._invoke_creator(self)
  File "/Users/dankmank/anaconda3/lib/python3.7/site-packages/sqlalchemy/engine/strategies.py", line 114, in connect
    return dialect.connect(*cargs, **cparams)
  File "/Users/dankmank/anaconda3/lib/python3.7/site-packages/sqlalchemy/engine/default.py", line 490, in connect
    return self.dbapi.connect(*cargs, **cparams)
  File "/Users/dankmank/anaconda3/lib/python3.7/site-packages/psycopg2/__init__.py", line 127, in connect
    conn = _connect(dsn, connection_factory=connection_factory, **kwasync)
psycopg2.OperationalError: FATAL:  too many connections for role "kdscstklqmukmb"


The above exception was the direct cause of the following exception:

Traceback (most recent call last):
  File "/Users/dankmank/anaconda3/lib/python3.7/site-packages/gunicorn/arbiter.py", line 583, in spawn_worker
    worker.init_process()
  File "/Users/dankmank/anaconda3/lib/python3.7/site-packages/gunicorn/workers/base.py", line 129, in init_process
    self.load_wsgi()
  File "/Users/dankmank/anaconda3/lib/python3.7/site-packages/gunicorn/workers/base.py", line 138, in load_wsgi
    self.wsgi = self.app.wsgi()
  File "/Users/dankmank/anaconda3/lib/python3.7/site-packages/gunicorn/app/base.py", line 67, in wsgi
    self.callable = self.load()
  File "/Users/dankmank/anaconda3/lib/python3.7/site-packages/psiturk/experiment_server.py", line 48, in load
    return util.import_app("psiturk.experiment:app")
  File "/Users/dankmank/anaconda3/lib/python3.7/site-packages/gunicorn/util.py", line 350, in import_app
    __import__(module)
  File "/Users/dankmank/anaconda3/lib/python3.7/site-packages/psiturk/experiment.py", line 89, in <module>
    init_db()
  File "/Users/dankmank/anaconda3/lib/python3.7/site-packages/psiturk/db.py", line 37, in init_db
    Base.metadata.create_all(bind=engine)
  File "/Users/dankmank/anaconda3/lib/python3.7/site-packages/sqlalchemy/sql/schema.py", line 4465, in create_all
    ddl.SchemaGenerator, self, checkfirst=checkfirst, tables=tables
  File "/Users/dankmank/anaconda3/lib/python3.7/site-packages/sqlalchemy/engine/base.py", line 2103, in _run_visitor
    with self._optional_conn_ctx_manager(connection) as conn:
  File "/Users/dankmank/anaconda3/lib/python3.7/contextlib.py", line 112, in __enter__
    return next(self.gen)
  File "/Users/dankmank/anaconda3/lib/python3.7/site-packages/sqlalchemy/engine/base.py", line 2095, in _optional_conn_ctx_manager
    with self._contextual_connect() as conn:
  File "/Users/dankmank/anaconda3/lib/python3.7/site-packages/sqlalchemy/engine/base.py", line 2311, in _contextual_connect
    self._wrap_pool_connect(self.pool.connect, None),
  File "/Users/dankmank/anaconda3/lib/python3.7/site-packages/sqlalchemy/engine/base.py", line 2349, in _wrap_pool_connect
    e, dialect, self
  File "/Users/dankmank/anaconda3/lib/python3.7/site-packages/sqlalchemy/engine/base.py", line 1591, in _handle_dbapi_exception_noconnection
    sqlalchemy_exception, with_traceback=exc_info[2], from_=e
  File "/Users/dankmank/anaconda3/lib/python3.7/site-packages/sqlalchemy/util/compat.py", line 178, in raise_
    raise exception
  File "/Users/dankmank/anaconda3/lib/python3.7/site-packages/sqlalchemy/engine/base.py", line 2345, in _wrap_pool_connect
    return fn()
  File "/Users/dankmank/anaconda3/lib/python3.7/site-packages/sqlalchemy/pool/base.py", line 364, in connect
    return _ConnectionFairy._checkout(self)
  File "/Users/dankmank/anaconda3/lib/python3.7/site-packages/sqlalchemy/pool/base.py", line 778, in _checkout
    fairy = _ConnectionRecord.checkout(pool)
  File "/Users/dankmank/anaconda3/lib/python3.7/site-packages/sqlalchemy/pool/base.py", line 495, in checkout
    rec = pool._do_get()
  File "/Users/dankmank/anaconda3/lib/python3.7/site-packages/sqlalchemy/pool/impl.py", line 140, in _do_get
    self._dec_overflow()
  File "/Users/dankmank/anaconda3/lib/python3.7/site-packages/sqlalchemy/util/langhelpers.py", line 69, in __exit__
    exc_value, with_traceback=exc_tb,
  File "/Users/dankmank/anaconda3/lib/python3.7/site-packages/sqlalchemy/util/compat.py", line 178, in raise_
    raise exception
  File "/Users/dankmank/anaconda3/lib/python3.7/site-packages/sqlalchemy/pool/impl.py", line 137, in _do_get
    return self._create_connection()
  File "/Users/dankmank/anaconda3/lib/python3.7/site-packages/sqlalchemy/pool/base.py", line 309, in _create_connection
    return _ConnectionRecord(self)
  File "/Users/dankmank/anaconda3/lib/python3.7/site-packages/sqlalchemy/pool/base.py", line 440, in __init__
    self.__connect(first_connect_check=True)
  File "/Users/dankmank/anaconda3/lib/python3.7/site-packages/sqlalchemy/pool/base.py", line 661, in __connect
    pool.logger.debug("Error on connect(): %s", e)
  File "/Users/dankmank/anaconda3/lib/python3.7/site-packages/sqlalchemy/util/langhelpers.py", line 69, in __exit__
    exc_value, with_traceback=exc_tb,
  File "/Users/dankmank/anaconda3/lib/python3.7/site-packages/sqlalchemy/util/compat.py", line 178, in raise_
    raise exception
  File "/Users/dankmank/anaconda3/lib/python3.7/site-packages/sqlalchemy/pool/base.py", line 656, in __connect
    connection = pool._invoke_creator(self)
  File "/Users/dankmank/anaconda3/lib/python3.7/site-packages/sqlalchemy/engine/strategies.py", line 114, in connect
    return dialect.connect(*cargs, **cparams)
  File "/Users/dankmank/anaconda3/lib/python3.7/site-packages/sqlalchemy/engine/default.py", line 490, in connect
    return self.dbapi.connect(*cargs, **cparams)
  File "/Users/dankmank/anaconda3/lib/python3.7/site-packages/psycopg2/__init__.py", line 127, in connect
    conn = _connect(dsn, connection_factory=connection_factory, **kwasync)
sqlalchemy.exc.OperationalError: (psycopg2.OperationalError) FATAL:  too many connections for role "kdscstklqmukmb"

(Background on this error at: http://sqlalche.me/e/e3q8)
[2020-07-07 17:15:29 -0700] [19131] [ERROR] Exception in worker process
Traceback (most recent call last):
  File "/Users/dankmank/anaconda3/lib/python3.7/site-packages/sqlalchemy/engine/base.py", line 2345, in _wrap_pool_connect
    return fn()
  File "/Users/dankmank/anaconda3/lib/python3.7/site-packages/sqlalchemy/pool/base.py", line 364, in connect
    return _ConnectionFairy._checkout(self)
  File "/Users/dankmank/anaconda3/lib/python3.7/site-packages/sqlalchemy/pool/base.py", line 778, in _checkout
    fairy = _ConnectionRecord.checkout(pool)
  File "/Users/dankmank/anaconda3/lib/python3.7/site-packages/sqlalchemy/pool/base.py", line 495, in checkout
    rec = pool._do_get()
  File "/Users/dankmank/anaconda3/lib/python3.7/site-packages/sqlalchemy/pool/impl.py", line 140, in _do_get
    self._dec_overflow()
  File "/Users/dankmank/anaconda3/lib/python3.7/site-packages/sqlalchemy/util/langhelpers.py", line 69, in __exit__
    exc_value, with_traceback=exc_tb,
  File "/Users/dankmank/anaconda3/lib/python3.7/site-packages/sqlalchemy/util/compat.py", line 178, in raise_
    raise exception
  File "/Users/dankmank/anaconda3/lib/python3.7/site-packages/sqlalchemy/pool/impl.py", line 137, in _do_get
    return self._create_connection()
  File "/Users/dankmank/anaconda3/lib/python3.7/site-packages/sqlalchemy/pool/base.py", line 309, in _create_connection
    return _ConnectionRecord(self)
  File "/Users/dankmank/anaconda3/lib/python3.7/site-packages/sqlalchemy/pool/base.py", line 440, in __init__
    self.__connect(first_connect_check=True)
  File "/Users/dankmank/anaconda3/lib/python3.7/site-packages/sqlalchemy/pool/base.py", line 661, in __connect
    pool.logger.debug("Error on connect(): %s", e)
  File "/Users/dankmank/anaconda3/lib/python3.7/site-packages/sqlalchemy/util/langhelpers.py", line 69, in __exit__
    exc_value, with_traceback=exc_tb,
  File "/Users/dankmank/anaconda3/lib/python3.7/site-packages/sqlalchemy/util/compat.py", line 178, in raise_
    raise exception
  File "/Users/dankmank/anaconda3/lib/python3.7/site-packages/sqlalchemy/pool/base.py", line 656, in __connect
    connection = pool._invoke_creator(self)
  File "/Users/dankmank/anaconda3/lib/python3.7/site-packages/sqlalchemy/engine/strategies.py", line 114, in connect
    return dialect.connect(*cargs, **cparams)
  File "/Users/dankmank/anaconda3/lib/python3.7/site-packages/sqlalchemy/engine/default.py", line 490, in connect
    return self.dbapi.connect(*cargs, **cparams)
  File "/Users/dankmank/anaconda3/lib/python3.7/site-packages/psycopg2/__init__.py", line 127, in connect
    conn = _connect(dsn, connection_factory=connection_factory, **kwasync)
psycopg2.OperationalError: FATAL:  too many connections for role "kdscstklqmukmb"


The above exception was the direct cause of the following exception:

Traceback (most recent call last):
  File "/Users/dankmank/anaconda3/lib/python3.7/site-packages/gunicorn/arbiter.py", line 583, in spawn_worker
    worker.init_process()
  File "/Users/dankmank/anaconda3/lib/python3.7/site-packages/gunicorn/workers/base.py", line 129, in init_process
    self.load_wsgi()
  File "/Users/dankmank/anaconda3/lib/python3.7/site-packages/gunicorn/workers/base.py", line 138, in load_wsgi
    self.wsgi = self.app.wsgi()
  File "/Users/dankmank/anaconda3/lib/python3.7/site-packages/gunicorn/app/base.py", line 67, in wsgi
    self.callable = self.load()
  File "/Users/dankmank/anaconda3/lib/python3.7/site-packages/psiturk/experiment_server.py", line 48, in load
    return util.import_app("psiturk.experiment:app")
  File "/Users/dankmank/anaconda3/lib/python3.7/site-packages/gunicorn/util.py", line 350, in import_app
    __import__(module)
  File "/Users/dankmank/anaconda3/lib/python3.7/site-packages/psiturk/experiment.py", line 89, in <module>
    init_db()
  File "/Users/dankmank/anaconda3/lib/python3.7/site-packages/psiturk/db.py", line 37, in init_db
    Base.metadata.create_all(bind=engine)
  File "/Users/dankmank/anaconda3/lib/python3.7/site-packages/sqlalchemy/sql/schema.py", line 4465, in create_all
    ddl.SchemaGenerator, self, checkfirst=checkfirst, tables=tables
  File "/Users/dankmank/anaconda3/lib/python3.7/site-packages/sqlalchemy/engine/base.py", line 2103, in _run_visitor
    with self._optional_conn_ctx_manager(connection) as conn:
  File "/Users/dankmank/anaconda3/lib/python3.7/contextlib.py", line 112, in __enter__
    return next(self.gen)
  File "/Users/dankmank/anaconda3/lib/python3.7/site-packages/sqlalchemy/engine/base.py", line 2095, in _optional_conn_ctx_manager
    with self._contextual_connect() as conn:
  File "/Users/dankmank/anaconda3/lib/python3.7/site-packages/sqlalchemy/engine/base.py", line 2311, in _contextual_connect
    self._wrap_pool_connect(self.pool.connect, None),
  File "/Users/dankmank/anaconda3/lib/python3.7/site-packages/sqlalchemy/engine/base.py", line 2349, in _wrap_pool_connect
    e, dialect, self
  File "/Users/dankmank/anaconda3/lib/python3.7/site-packages/sqlalchemy/engine/base.py", line 1591, in _handle_dbapi_exception_noconnection
    sqlalchemy_exception, with_traceback=exc_info[2], from_=e
  File "/Users/dankmank/anaconda3/lib/python3.7/site-packages/sqlalchemy/util/compat.py", line 178, in raise_
    raise exception
  File "/Users/dankmank/anaconda3/lib/python3.7/site-packages/sqlalchemy/engine/base.py", line 2345, in _wrap_pool_connect
    return fn()
  File "/Users/dankmank/anaconda3/lib/python3.7/site-packages/sqlalchemy/pool/base.py", line 364, in connect
    return _ConnectionFairy._checkout(self)
  File "/Users/dankmank/anaconda3/lib/python3.7/site-packages/sqlalchemy/pool/base.py", line 778, in _checkout
    fairy = _ConnectionRecord.checkout(pool)
  File "/Users/dankmank/anaconda3/lib/python3.7/site-packages/sqlalchemy/pool/base.py", line 495, in checkout
    rec = pool._do_get()
  File "/Users/dankmank/anaconda3/lib/python3.7/site-packages/sqlalchemy/pool/impl.py", line 140, in _do_get
    self._dec_overflow()
  File "/Users/dankmank/anaconda3/lib/python3.7/site-packages/sqlalchemy/util/langhelpers.py", line 69, in __exit__
    exc_value, with_traceback=exc_tb,
  File "/Users/dankmank/anaconda3/lib/python3.7/site-packages/sqlalchemy/util/compat.py", line 178, in raise_
    raise exception
  File "/Users/dankmank/anaconda3/lib/python3.7/site-packages/sqlalchemy/pool/impl.py", line 137, in _do_get
    return self._create_connection()
  File "/Users/dankmank/anaconda3/lib/python3.7/site-packages/sqlalchemy/pool/base.py", line 309, in _create_connection
    return _ConnectionRecord(self)
  File "/Users/dankmank/anaconda3/lib/python3.7/site-packages/sqlalchemy/pool/base.py", line 440, in __init__
    self.__connect(first_connect_check=True)
  File "/Users/dankmank/anaconda3/lib/python3.7/site-packages/sqlalchemy/pool/base.py", line 661, in __connect
    pool.logger.debug("Error on connect(): %s", e)
  File "/Users/dankmank/anaconda3/lib/python3.7/site-packages/sqlalchemy/util/langhelpers.py", line 69, in __exit__
    exc_value, with_traceback=exc_tb,
  File "/Users/dankmank/anaconda3/lib/python3.7/site-packages/sqlalchemy/util/compat.py", line 178, in raise_
    raise exception
  File "/Users/dankmank/anaconda3/lib/python3.7/site-packages/sqlalchemy/pool/base.py", line 656, in __connect
    connection = pool._invoke_creator(self)
  File "/Users/dankmank/anaconda3/lib/python3.7/site-packages/sqlalchemy/engine/strategies.py", line 114, in connect
    return dialect.connect(*cargs, **cparams)
  File "/Users/dankmank/anaconda3/lib/python3.7/site-packages/sqlalchemy/engine/default.py", line 490, in connect
    return self.dbapi.connect(*cargs, **cparams)
  File "/Users/dankmank/anaconda3/lib/python3.7/site-packages/psycopg2/__init__.py", line 127, in connect
    conn = _connect(dsn, connection_factory=connection_factory, **kwasync)
sqlalchemy.exc.OperationalError: (psycopg2.OperationalError) FATAL:  too many connections for role "kdscstklqmukmb"

(Background on this error at: http://sqlalche.me/e/e3q8)
[2020-07-07 17:15:29 -0700] [19132] [ERROR] Exception in worker process
Traceback (most recent call last):
  File "/Users/dankmank/anaconda3/lib/python3.7/site-packages/sqlalchemy/engine/base.py", line 2345, in _wrap_pool_connect
    return fn()
  File "/Users/dankmank/anaconda3/lib/python3.7/site-packages/sqlalchemy/pool/base.py", line 364, in connect
    return _ConnectionFairy._checkout(self)
  File "/Users/dankmank/anaconda3/lib/python3.7/site-packages/sqlalchemy/pool/base.py", line 778, in _checkout
    fairy = _ConnectionRecord.checkout(pool)
  File "/Users/dankmank/anaconda3/lib/python3.7/site-packages/sqlalchemy/pool/base.py", line 495, in checkout
    rec = pool._do_get()
  File "/Users/dankmank/anaconda3/lib/python3.7/site-packages/sqlalchemy/pool/impl.py", line 140, in _do_get
    self._dec_overflow()
  File "/Users/dankmank/anaconda3/lib/python3.7/site-packages/sqlalchemy/util/langhelpers.py", line 69, in __exit__
    exc_value, with_traceback=exc_tb,
  File "/Users/dankmank/anaconda3/lib/python3.7/site-packages/sqlalchemy/util/compat.py", line 178, in raise_
    raise exception
  File "/Users/dankmank/anaconda3/lib/python3.7/site-packages/sqlalchemy/pool/impl.py", line 137, in _do_get
    return self._create_connection()
  File "/Users/dankmank/anaconda3/lib/python3.7/site-packages/sqlalchemy/pool/base.py", line 309, in _create_connection
    return _ConnectionRecord(self)
  File "/Users/dankmank/anaconda3/lib/python3.7/site-packages/sqlalchemy/pool/base.py", line 440, in __init__
    self.__connect(first_connect_check=True)
  File "/Users/dankmank/anaconda3/lib/python3.7/site-packages/sqlalchemy/pool/base.py", line 661, in __connect
    pool.logger.debug("Error on connect(): %s", e)
  File "/Users/dankmank/anaconda3/lib/python3.7/site-packages/sqlalchemy/util/langhelpers.py", line 69, in __exit__
    exc_value, with_traceback=exc_tb,
  File "/Users/dankmank/anaconda3/lib/python3.7/site-packages/sqlalchemy/util/compat.py", line 178, in raise_
    raise exception
  File "/Users/dankmank/anaconda3/lib/python3.7/site-packages/sqlalchemy/pool/base.py", line 656, in __connect
    connection = pool._invoke_creator(self)
  File "/Users/dankmank/anaconda3/lib/python3.7/site-packages/sqlalchemy/engine/strategies.py", line 114, in connect
    return dialect.connect(*cargs, **cparams)
  File "/Users/dankmank/anaconda3/lib/python3.7/site-packages/sqlalchemy/engine/default.py", line 490, in connect
    return self.dbapi.connect(*cargs, **cparams)
  File "/Users/dankmank/anaconda3/lib/python3.7/site-packages/psycopg2/__init__.py", line 127, in connect
    conn = _connect(dsn, connection_factory=connection_factory, **kwasync)
psycopg2.OperationalError: FATAL:  too many connections for role "kdscstklqmukmb"


The above exception was the direct cause of the following exception:

Traceback (most recent call last):
  File "/Users/dankmank/anaconda3/lib/python3.7/site-packages/gunicorn/arbiter.py", line 583, in spawn_worker
    worker.init_process()
  File "/Users/dankmank/anaconda3/lib/python3.7/site-packages/gunicorn/workers/base.py", line 129, in init_process
    self.load_wsgi()
  File "/Users/dankmank/anaconda3/lib/python3.7/site-packages/gunicorn/workers/base.py", line 138, in load_wsgi
    self.wsgi = self.app.wsgi()
  File "/Users/dankmank/anaconda3/lib/python3.7/site-packages/gunicorn/app/base.py", line 67, in wsgi
    self.callable = self.load()
  File "/Users/dankmank/anaconda3/lib/python3.7/site-packages/psiturk/experiment_server.py", line 48, in load
    return util.import_app("psiturk.experiment:app")
  File "/Users/dankmank/anaconda3/lib/python3.7/site-packages/gunicorn/util.py", line 350, in import_app
    __import__(module)
  File "/Users/dankmank/anaconda3/lib/python3.7/site-packages/psiturk/experiment.py", line 89, in <module>
    init_db()
  File "/Users/dankmank/anaconda3/lib/python3.7/site-packages/psiturk/db.py", line 37, in init_db
    Base.metadata.create_all(bind=engine)
  File "/Users/dankmank/anaconda3/lib/python3.7/site-packages/sqlalchemy/sql/schema.py", line 4465, in create_all
    ddl.SchemaGenerator, self, checkfirst=checkfirst, tables=tables
  File "/Users/dankmank/anaconda3/lib/python3.7/site-packages/sqlalchemy/engine/base.py", line 2103, in _run_visitor
    with self._optional_conn_ctx_manager(connection) as conn:
  File "/Users/dankmank/anaconda3/lib/python3.7/contextlib.py", line 112, in __enter__
    return next(self.gen)
  File "/Users/dankmank/anaconda3/lib/python3.7/site-packages/sqlalchemy/engine/base.py", line 2095, in _optional_conn_ctx_manager
    with self._contextual_connect() as conn:
  File "/Users/dankmank/anaconda3/lib/python3.7/site-packages/sqlalchemy/engine/base.py", line 2311, in _contextual_connect
    self._wrap_pool_connect(self.pool.connect, None),
  File "/Users/dankmank/anaconda3/lib/python3.7/site-packages/sqlalchemy/engine/base.py", line 2349, in _wrap_pool_connect
    e, dialect, self
  File "/Users/dankmank/anaconda3/lib/python3.7/site-packages/sqlalchemy/engine/base.py", line 1591, in _handle_dbapi_exception_noconnection
    sqlalchemy_exception, with_traceback=exc_info[2], from_=e
  File "/Users/dankmank/anaconda3/lib/python3.7/site-packages/sqlalchemy/util/compat.py", line 178, in raise_
    raise exception
  File "/Users/dankmank/anaconda3/lib/python3.7/site-packages/sqlalchemy/engine/base.py", line 2345, in _wrap_pool_connect
    return fn()
  File "/Users/dankmank/anaconda3/lib/python3.7/site-packages/sqlalchemy/pool/base.py", line 364, in connect
    return _ConnectionFairy._checkout(self)
  File "/Users/dankmank/anaconda3/lib/python3.7/site-packages/sqlalchemy/pool/base.py", line 778, in _checkout
    fairy = _ConnectionRecord.checkout(pool)
  File "/Users/dankmank/anaconda3/lib/python3.7/site-packages/sqlalchemy/pool/base.py", line 495, in checkout
    rec = pool._do_get()
  File "/Users/dankmank/anaconda3/lib/python3.7/site-packages/sqlalchemy/pool/impl.py", line 140, in _do_get
    self._dec_overflow()
  File "/Users/dankmank/anaconda3/lib/python3.7/site-packages/sqlalchemy/util/langhelpers.py", line 69, in __exit__
    exc_value, with_traceback=exc_tb,
  File "/Users/dankmank/anaconda3/lib/python3.7/site-packages/sqlalchemy/util/compat.py", line 178, in raise_
    raise exception
  File "/Users/dankmank/anaconda3/lib/python3.7/site-packages/sqlalchemy/pool/impl.py", line 137, in _do_get
    return self._create_connection()
  File "/Users/dankmank/anaconda3/lib/python3.7/site-packages/sqlalchemy/pool/base.py", line 309, in _create_connection
    return _ConnectionRecord(self)
  File "/Users/dankmank/anaconda3/lib/python3.7/site-packages/sqlalchemy/pool/base.py", line 440, in __init__
    self.__connect(first_connect_check=True)
  File "/Users/dankmank/anaconda3/lib/python3.7/site-packages/sqlalchemy/pool/base.py", line 661, in __connect
    pool.logger.debug("Error on connect(): %s", e)
  File "/Users/dankmank/anaconda3/lib/python3.7/site-packages/sqlalchemy/util/langhelpers.py", line 69, in __exit__
    exc_value, with_traceback=exc_tb,
  File "/Users/dankmank/anaconda3/lib/python3.7/site-packages/sqlalchemy/util/compat.py", line 178, in raise_
    raise exception
  File "/Users/dankmank/anaconda3/lib/python3.7/site-packages/sqlalchemy/pool/base.py", line 656, in __connect
    connection = pool._invoke_creator(self)
  File "/Users/dankmank/anaconda3/lib/python3.7/site-packages/sqlalchemy/engine/strategies.py", line 114, in connect
    return dialect.connect(*cargs, **cparams)
  File "/Users/dankmank/anaconda3/lib/python3.7/site-packages/sqlalchemy/engine/default.py", line 490, in connect
    return self.dbapi.connect(*cargs, **cparams)
  File "/Users/dankmank/anaconda3/lib/python3.7/site-packages/psycopg2/__init__.py", line 127, in connect
    conn = _connect(dsn, connection_factory=connection_factory, **kwasync)
sqlalchemy.exc.OperationalError: (psycopg2.OperationalError) FATAL:  too many connections for role "kdscstklqmukmb"

(Background on this error at: http://sqlalche.me/e/e3q8)
[2020-07-07 17:15:29 -0700] [19133] [ERROR] Exception in worker process
Traceback (most recent call last):
  File "/Users/dankmank/anaconda3/lib/python3.7/site-packages/sqlalchemy/engine/base.py", line 2345, in _wrap_pool_connect
    return fn()
  File "/Users/dankmank/anaconda3/lib/python3.7/site-packages/sqlalchemy/pool/base.py", line 364, in connect
    return _ConnectionFairy._checkout(self)
  File "/Users/dankmank/anaconda3/lib/python3.7/site-packages/sqlalchemy/pool/base.py", line 778, in _checkout
    fairy = _ConnectionRecord.checkout(pool)
  File "/Users/dankmank/anaconda3/lib/python3.7/site-packages/sqlalchemy/pool/base.py", line 495, in checkout
    rec = pool._do_get()
  File "/Users/dankmank/anaconda3/lib/python3.7/site-packages/sqlalchemy/pool/impl.py", line 140, in _do_get
    self._dec_overflow()
  File "/Users/dankmank/anaconda3/lib/python3.7/site-packages/sqlalchemy/util/langhelpers.py", line 69, in __exit__
    exc_value, with_traceback=exc_tb,
  File "/Users/dankmank/anaconda3/lib/python3.7/site-packages/sqlalchemy/util/compat.py", line 178, in raise_
    raise exception
  File "/Users/dankmank/anaconda3/lib/python3.7/site-packages/sqlalchemy/pool/impl.py", line 137, in _do_get
    return self._create_connection()
  File "/Users/dankmank/anaconda3/lib/python3.7/site-packages/sqlalchemy/pool/base.py", line 309, in _create_connection
    return _ConnectionRecord(self)
  File "/Users/dankmank/anaconda3/lib/python3.7/site-packages/sqlalchemy/pool/base.py", line 440, in __init__
    self.__connect(first_connect_check=True)
  File "/Users/dankmank/anaconda3/lib/python3.7/site-packages/sqlalchemy/pool/base.py", line 661, in __connect
    pool.logger.debug("Error on connect(): %s", e)
  File "/Users/dankmank/anaconda3/lib/python3.7/site-packages/sqlalchemy/util/langhelpers.py", line 69, in __exit__
    exc_value, with_traceback=exc_tb,
  File "/Users/dankmank/anaconda3/lib/python3.7/site-packages/sqlalchemy/util/compat.py", line 178, in raise_
    raise exception
  File "/Users/dankmank/anaconda3/lib/python3.7/site-packages/sqlalchemy/pool/base.py", line 656, in __connect
    connection = pool._invoke_creator(self)
  File "/Users/dankmank/anaconda3/lib/python3.7/site-packages/sqlalchemy/engine/strategies.py", line 114, in connect
    return dialect.connect(*cargs, **cparams)
  File "/Users/dankmank/anaconda3/lib/python3.7/site-packages/sqlalchemy/engine/default.py", line 490, in connect
    return self.dbapi.connect(*cargs, **cparams)
  File "/Users/dankmank/anaconda3/lib/python3.7/site-packages/psycopg2/__init__.py", line 127, in connect
    conn = _connect(dsn, connection_factory=connection_factory, **kwasync)
psycopg2.OperationalError: FATAL:  too many connections for role "kdscstklqmukmb"


The above exception was the direct cause of the following exception:

Traceback (most recent call last):
  File "/Users/dankmank/anaconda3/lib/python3.7/site-packages/gunicorn/arbiter.py", line 583, in spawn_worker
    worker.init_process()
  File "/Users/dankmank/anaconda3/lib/python3.7/site-packages/gunicorn/workers/base.py", line 129, in init_process
    self.load_wsgi()
  File "/Users/dankmank/anaconda3/lib/python3.7/site-packages/gunicorn/workers/base.py", line 138, in load_wsgi
    self.wsgi = self.app.wsgi()
  File "/Users/dankmank/anaconda3/lib/python3.7/site-packages/gunicorn/app/base.py", line 67, in wsgi
    self.callable = self.load()
  File "/Users/dankmank/anaconda3/lib/python3.7/site-packages/psiturk/experiment_server.py", line 48, in load
    return util.import_app("psiturk.experiment:app")
  File "/Users/dankmank/anaconda3/lib/python3.7/site-packages/gunicorn/util.py", line 350, in import_app
    __import__(module)
  File "/Users/dankmank/anaconda3/lib/python3.7/site-packages/psiturk/experiment.py", line 89, in <module>
    init_db()
  File "/Users/dankmank/anaconda3/lib/python3.7/site-packages/psiturk/db.py", line 37, in init_db
    Base.metadata.create_all(bind=engine)
  File "/Users/dankmank/anaconda3/lib/python3.7/site-packages/sqlalchemy/sql/schema.py", line 4465, in create_all
    ddl.SchemaGenerator, self, checkfirst=checkfirst, tables=tables
  File "/Users/dankmank/anaconda3/lib/python3.7/site-packages/sqlalchemy/engine/base.py", line 2103, in _run_visitor
    with self._optional_conn_ctx_manager(connection) as conn:
  File "/Users/dankmank/anaconda3/lib/python3.7/contextlib.py", line 112, in __enter__
    return next(self.gen)
  File "/Users/dankmank/anaconda3/lib/python3.7/site-packages/sqlalchemy/engine/base.py", line 2095, in _optional_conn_ctx_manager
    with self._contextual_connect() as conn:
  File "/Users/dankmank/anaconda3/lib/python3.7/site-packages/sqlalchemy/engine/base.py", line 2311, in _contextual_connect
    self._wrap_pool_connect(self.pool.connect, None),
  File "/Users/dankmank/anaconda3/lib/python3.7/site-packages/sqlalchemy/engine/base.py", line 2349, in _wrap_pool_connect
    e, dialect, self
  File "/Users/dankmank/anaconda3/lib/python3.7/site-packages/sqlalchemy/engine/base.py", line 1591, in _handle_dbapi_exception_noconnection
    sqlalchemy_exception, with_traceback=exc_info[2], from_=e
  File "/Users/dankmank/anaconda3/lib/python3.7/site-packages/sqlalchemy/util/compat.py", line 178, in raise_
    raise exception
  File "/Users/dankmank/anaconda3/lib/python3.7/site-packages/sqlalchemy/engine/base.py", line 2345, in _wrap_pool_connect
    return fn()
  File "/Users/dankmank/anaconda3/lib/python3.7/site-packages/sqlalchemy/pool/base.py", line 364, in connect
    return _ConnectionFairy._checkout(self)
  File "/Users/dankmank/anaconda3/lib/python3.7/site-packages/sqlalchemy/pool/base.py", line 778, in _checkout
    fairy = _ConnectionRecord.checkout(pool)
  File "/Users/dankmank/anaconda3/lib/python3.7/site-packages/sqlalchemy/pool/base.py", line 495, in checkout
    rec = pool._do_get()
  File "/Users/dankmank/anaconda3/lib/python3.7/site-packages/sqlalchemy/pool/impl.py", line 140, in _do_get
    self._dec_overflow()
  File "/Users/dankmank/anaconda3/lib/python3.7/site-packages/sqlalchemy/util/langhelpers.py", line 69, in __exit__
    exc_value, with_traceback=exc_tb,
  File "/Users/dankmank/anaconda3/lib/python3.7/site-packages/sqlalchemy/util/compat.py", line 178, in raise_
    raise exception
  File "/Users/dankmank/anaconda3/lib/python3.7/site-packages/sqlalchemy/pool/impl.py", line 137, in _do_get
    return self._create_connection()
  File "/Users/dankmank/anaconda3/lib/python3.7/site-packages/sqlalchemy/pool/base.py", line 309, in _create_connection
    return _ConnectionRecord(self)
  File "/Users/dankmank/anaconda3/lib/python3.7/site-packages/sqlalchemy/pool/base.py", line 440, in __init__
    self.__connect(first_connect_check=True)
  File "/Users/dankmank/anaconda3/lib/python3.7/site-packages/sqlalchemy/pool/base.py", line 661, in __connect
    pool.logger.debug("Error on connect(): %s", e)
  File "/Users/dankmank/anaconda3/lib/python3.7/site-packages/sqlalchemy/util/langhelpers.py", line 69, in __exit__
    exc_value, with_traceback=exc_tb,
  File "/Users/dankmank/anaconda3/lib/python3.7/site-packages/sqlalchemy/util/compat.py", line 178, in raise_
    raise exception
  File "/Users/dankmank/anaconda3/lib/python3.7/site-packages/sqlalchemy/pool/base.py", line 656, in __connect
    connection = pool._invoke_creator(self)
  File "/Users/dankmank/anaconda3/lib/python3.7/site-packages/sqlalchemy/engine/strategies.py", line 114, in connect
    return dialect.connect(*cargs, **cparams)
  File "/Users/dankmank/anaconda3/lib/python3.7/site-packages/sqlalchemy/engine/default.py", line 490, in connect
    return self.dbapi.connect(*cargs, **cparams)
  File "/Users/dankmank/anaconda3/lib/python3.7/site-packages/psycopg2/__init__.py", line 127, in connect
    conn = _connect(dsn, connection_factory=connection_factory, **kwasync)
sqlalchemy.exc.OperationalError: (psycopg2.OperationalError) FATAL:  too many connections for role "kdscstklqmukmb"

(Background on this error at: http://sqlalche.me/e/e3q8)
[2020-07-07 17:15:29 -0700] [19134] [ERROR] Exception in worker process
Traceback (most recent call last):
  File "/Users/dankmank/anaconda3/lib/python3.7/site-packages/sqlalchemy/engine/base.py", line 2345, in _wrap_pool_connect
    return fn()
  File "/Users/dankmank/anaconda3/lib/python3.7/site-packages/sqlalchemy/pool/base.py", line 364, in connect
    return _ConnectionFairy._checkout(self)
  File "/Users/dankmank/anaconda3/lib/python3.7/site-packages/sqlalchemy/pool/base.py", line 778, in _checkout
    fairy = _ConnectionRecord.checkout(pool)
  File "/Users/dankmank/anaconda3/lib/python3.7/site-packages/sqlalchemy/pool/base.py", line 495, in checkout
    rec = pool._do_get()
  File "/Users/dankmank/anaconda3/lib/python3.7/site-packages/sqlalchemy/pool/impl.py", line 140, in _do_get
    self._dec_overflow()
  File "/Users/dankmank/anaconda3/lib/python3.7/site-packages/sqlalchemy/util/langhelpers.py", line 69, in __exit__
    exc_value, with_traceback=exc_tb,
  File "/Users/dankmank/anaconda3/lib/python3.7/site-packages/sqlalchemy/util/compat.py", line 178, in raise_
    raise exception
  File "/Users/dankmank/anaconda3/lib/python3.7/site-packages/sqlalchemy/pool/impl.py", line 137, in _do_get
    return self._create_connection()
  File "/Users/dankmank/anaconda3/lib/python3.7/site-packages/sqlalchemy/pool/base.py", line 309, in _create_connection
    return _ConnectionRecord(self)
  File "/Users/dankmank/anaconda3/lib/python3.7/site-packages/sqlalchemy/pool/base.py", line 440, in __init__
    self.__connect(first_connect_check=True)
  File "/Users/dankmank/anaconda3/lib/python3.7/site-packages/sqlalchemy/pool/base.py", line 661, in __connect
    pool.logger.debug("Error on connect(): %s", e)
  File "/Users/dankmank/anaconda3/lib/python3.7/site-packages/sqlalchemy/util/langhelpers.py", line 69, in __exit__
    exc_value, with_traceback=exc_tb,
  File "/Users/dankmank/anaconda3/lib/python3.7/site-packages/sqlalchemy/util/compat.py", line 178, in raise_
    raise exception
  File "/Users/dankmank/anaconda3/lib/python3.7/site-packages/sqlalchemy/pool/base.py", line 656, in __connect
    connection = pool._invoke_creator(self)
  File "/Users/dankmank/anaconda3/lib/python3.7/site-packages/sqlalchemy/engine/strategies.py", line 114, in connect
    return dialect.connect(*cargs, **cparams)
  File "/Users/dankmank/anaconda3/lib/python3.7/site-packages/sqlalchemy/engine/default.py", line 490, in connect
    return self.dbapi.connect(*cargs, **cparams)
  File "/Users/dankmank/anaconda3/lib/python3.7/site-packages/psycopg2/__init__.py", line 127, in connect
    conn = _connect(dsn, connection_factory=connection_factory, **kwasync)
psycopg2.OperationalError: FATAL:  too many connections for role "kdscstklqmukmb"


The above exception was the direct cause of the following exception:

Traceback (most recent call last):
  File "/Users/dankmank/anaconda3/lib/python3.7/site-packages/gunicorn/arbiter.py", line 583, in spawn_worker
    worker.init_process()
  File "/Users/dankmank/anaconda3/lib/python3.7/site-packages/gunicorn/workers/base.py", line 129, in init_process
    self.load_wsgi()
  File "/Users/dankmank/anaconda3/lib/python3.7/site-packages/gunicorn/workers/base.py", line 138, in load_wsgi
    self.wsgi = self.app.wsgi()
  File "/Users/dankmank/anaconda3/lib/python3.7/site-packages/gunicorn/app/base.py", line 67, in wsgi
    self.callable = self.load()
  File "/Users/dankmank/anaconda3/lib/python3.7/site-packages/psiturk/experiment_server.py", line 48, in load
    return util.import_app("psiturk.experiment:app")
  File "/Users/dankmank/anaconda3/lib/python3.7/site-packages/gunicorn/util.py", line 350, in import_app
    __import__(module)
  File "/Users/dankmank/anaconda3/lib/python3.7/site-packages/psiturk/experiment.py", line 89, in <module>
    init_db()
  File "/Users/dankmank/anaconda3/lib/python3.7/site-packages/psiturk/db.py", line 37, in init_db
    Base.metadata.create_all(bind=engine)
  File "/Users/dankmank/anaconda3/lib/python3.7/site-packages/sqlalchemy/sql/schema.py", line 4465, in create_all
    ddl.SchemaGenerator, self, checkfirst=checkfirst, tables=tables
  File "/Users/dankmank/anaconda3/lib/python3.7/site-packages/sqlalchemy/engine/base.py", line 2103, in _run_visitor
    with self._optional_conn_ctx_manager(connection) as conn:
  File "/Users/dankmank/anaconda3/lib/python3.7/contextlib.py", line 112, in __enter__
    return next(self.gen)
  File "/Users/dankmank/anaconda3/lib/python3.7/site-packages/sqlalchemy/engine/base.py", line 2095, in _optional_conn_ctx_manager
    with self._contextual_connect() as conn:
  File "/Users/dankmank/anaconda3/lib/python3.7/site-packages/sqlalchemy/engine/base.py", line 2311, in _contextual_connect
    self._wrap_pool_connect(self.pool.connect, None),
  File "/Users/dankmank/anaconda3/lib/python3.7/site-packages/sqlalchemy/engine/base.py", line 2349, in _wrap_pool_connect
    e, dialect, self
  File "/Users/dankmank/anaconda3/lib/python3.7/site-packages/sqlalchemy/engine/base.py", line 1591, in _handle_dbapi_exception_noconnection
    sqlalchemy_exception, with_traceback=exc_info[2], from_=e
  File "/Users/dankmank/anaconda3/lib/python3.7/site-packages/sqlalchemy/util/compat.py", line 178, in raise_
    raise exception
  File "/Users/dankmank/anaconda3/lib/python3.7/site-packages/sqlalchemy/engine/base.py", line 2345, in _wrap_pool_connect
    return fn()
  File "/Users/dankmank/anaconda3/lib/python3.7/site-packages/sqlalchemy/pool/base.py", line 364, in connect
    return _ConnectionFairy._checkout(self)
  File "/Users/dankmank/anaconda3/lib/python3.7/site-packages/sqlalchemy/pool/base.py", line 778, in _checkout
    fairy = _ConnectionRecord.checkout(pool)
  File "/Users/dankmank/anaconda3/lib/python3.7/site-packages/sqlalchemy/pool/base.py", line 495, in checkout
    rec = pool._do_get()
  File "/Users/dankmank/anaconda3/lib/python3.7/site-packages/sqlalchemy/pool/impl.py", line 140, in _do_get
    self._dec_overflow()
  File "/Users/dankmank/anaconda3/lib/python3.7/site-packages/sqlalchemy/util/langhelpers.py", line 69, in __exit__
    exc_value, with_traceback=exc_tb,
  File "/Users/dankmank/anaconda3/lib/python3.7/site-packages/sqlalchemy/util/compat.py", line 178, in raise_
    raise exception
  File "/Users/dankmank/anaconda3/lib/python3.7/site-packages/sqlalchemy/pool/impl.py", line 137, in _do_get
    return self._create_connection()
  File "/Users/dankmank/anaconda3/lib/python3.7/site-packages/sqlalchemy/pool/base.py", line 309, in _create_connection
    return _ConnectionRecord(self)
  File "/Users/dankmank/anaconda3/lib/python3.7/site-packages/sqlalchemy/pool/base.py", line 440, in __init__
    self.__connect(first_connect_check=True)
  File "/Users/dankmank/anaconda3/lib/python3.7/site-packages/sqlalchemy/pool/base.py", line 661, in __connect
    pool.logger.debug("Error on connect(): %s", e)
  File "/Users/dankmank/anaconda3/lib/python3.7/site-packages/sqlalchemy/util/langhelpers.py", line 69, in __exit__
    exc_value, with_traceback=exc_tb,
  File "/Users/dankmank/anaconda3/lib/python3.7/site-packages/sqlalchemy/util/compat.py", line 178, in raise_
    raise exception
  File "/Users/dankmank/anaconda3/lib/python3.7/site-packages/sqlalchemy/pool/base.py", line 656, in __connect
    connection = pool._invoke_creator(self)
  File "/Users/dankmank/anaconda3/lib/python3.7/site-packages/sqlalchemy/engine/strategies.py", line 114, in connect
    return dialect.connect(*cargs, **cparams)
  File "/Users/dankmank/anaconda3/lib/python3.7/site-packages/sqlalchemy/engine/default.py", line 490, in connect
    return self.dbapi.connect(*cargs, **cparams)
  File "/Users/dankmank/anaconda3/lib/python3.7/site-packages/psycopg2/__init__.py", line 127, in connect
    conn = _connect(dsn, connection_factory=connection_factory, **kwasync)
sqlalchemy.exc.OperationalError: (psycopg2.OperationalError) FATAL:  too many connections for role "kdscstklqmukmb"

(Background on this error at: http://sqlalche.me/e/e3q8)
[2020-07-07 17:15:29 -0700] [19136] [ERROR] Exception in worker process
Traceback (most recent call last):
  File "/Users/dankmank/anaconda3/lib/python3.7/site-packages/sqlalchemy/engine/base.py", line 2345, in _wrap_pool_connect
    return fn()
  File "/Users/dankmank/anaconda3/lib/python3.7/site-packages/sqlalchemy/pool/base.py", line 364, in connect
    return _ConnectionFairy._checkout(self)
  File "/Users/dankmank/anaconda3/lib/python3.7/site-packages/sqlalchemy/pool/base.py", line 778, in _checkout
    fairy = _ConnectionRecord.checkout(pool)
  File "/Users/dankmank/anaconda3/lib/python3.7/site-packages/sqlalchemy/pool/base.py", line 495, in checkout
    rec = pool._do_get()
  File "/Users/dankmank/anaconda3/lib/python3.7/site-packages/sqlalchemy/pool/impl.py", line 140, in _do_get
    self._dec_overflow()
  File "/Users/dankmank/anaconda3/lib/python3.7/site-packages/sqlalchemy/util/langhelpers.py", line 69, in __exit__
    exc_value, with_traceback=exc_tb,
  File "/Users/dankmank/anaconda3/lib/python3.7/site-packages/sqlalchemy/util/compat.py", line 178, in raise_
    raise exception
  File "/Users/dankmank/anaconda3/lib/python3.7/site-packages/sqlalchemy/pool/impl.py", line 137, in _do_get
    return self._create_connection()
  File "/Users/dankmank/anaconda3/lib/python3.7/site-packages/sqlalchemy/pool/base.py", line 309, in _create_connection
    return _ConnectionRecord(self)
  File "/Users/dankmank/anaconda3/lib/python3.7/site-packages/sqlalchemy/pool/base.py", line 440, in __init__
    self.__connect(first_connect_check=True)
  File "/Users/dankmank/anaconda3/lib/python3.7/site-packages/sqlalchemy/pool/base.py", line 661, in __connect
    pool.logger.debug("Error on connect(): %s", e)
  File "/Users/dankmank/anaconda3/lib/python3.7/site-packages/sqlalchemy/util/langhelpers.py", line 69, in __exit__
    exc_value, with_traceback=exc_tb,
  File "/Users/dankmank/anaconda3/lib/python3.7/site-packages/sqlalchemy/util/compat.py", line 178, in raise_
    raise exception
  File "/Users/dankmank/anaconda3/lib/python3.7/site-packages/sqlalchemy/pool/base.py", line 656, in __connect
    connection = pool._invoke_creator(self)
  File "/Users/dankmank/anaconda3/lib/python3.7/site-packages/sqlalchemy/engine/strategies.py", line 114, in connect
    return dialect.connect(*cargs, **cparams)
  File "/Users/dankmank/anaconda3/lib/python3.7/site-packages/sqlalchemy/engine/default.py", line 490, in connect
    return self.dbapi.connect(*cargs, **cparams)
  File "/Users/dankmank/anaconda3/lib/python3.7/site-packages/psycopg2/__init__.py", line 127, in connect
    conn = _connect(dsn, connection_factory=connection_factory, **kwasync)
psycopg2.OperationalError: FATAL:  too many connections for role "kdscstklqmukmb"


The above exception was the direct cause of the following exception:

Traceback (most recent call last):
  File "/Users/dankmank/anaconda3/lib/python3.7/site-packages/gunicorn/arbiter.py", line 583, in spawn_worker
    worker.init_process()
  File "/Users/dankmank/anaconda3/lib/python3.7/site-packages/gunicorn/workers/base.py", line 129, in init_process
    self.load_wsgi()
  File "/Users/dankmank/anaconda3/lib/python3.7/site-packages/gunicorn/workers/base.py", line 138, in load_wsgi
    self.wsgi = self.app.wsgi()
  File "/Users/dankmank/anaconda3/lib/python3.7/site-packages/gunicorn/app/base.py", line 67, in wsgi
    self.callable = self.load()
  File "/Users/dankmank/anaconda3/lib/python3.7/site-packages/psiturk/experiment_server.py", line 48, in load
    return util.import_app("psiturk.experiment:app")
  File "/Users/dankmank/anaconda3/lib/python3.7/site-packages/gunicorn/util.py", line 350, in import_app
    __import__(module)
  File "/Users/dankmank/anaconda3/lib/python3.7/site-packages/psiturk/experiment.py", line 89, in <module>
    init_db()
  File "/Users/dankmank/anaconda3/lib/python3.7/site-packages/psiturk/db.py", line 37, in init_db
    Base.metadata.create_all(bind=engine)
  File "/Users/dankmank/anaconda3/lib/python3.7/site-packages/sqlalchemy/sql/schema.py", line 4465, in create_all
    ddl.SchemaGenerator, self, checkfirst=checkfirst, tables=tables
  File "/Users/dankmank/anaconda3/lib/python3.7/site-packages/sqlalchemy/engine/base.py", line 2103, in _run_visitor
    with self._optional_conn_ctx_manager(connection) as conn:
  File "/Users/dankmank/anaconda3/lib/python3.7/contextlib.py", line 112, in __enter__
    return next(self.gen)
  File "/Users/dankmank/anaconda3/lib/python3.7/site-packages/sqlalchemy/engine/base.py", line 2095, in _optional_conn_ctx_manager
    with self._contextual_connect() as conn:
  File "/Users/dankmank/anaconda3/lib/python3.7/site-packages/sqlalchemy/engine/base.py", line 2311, in _contextual_connect
    self._wrap_pool_connect(self.pool.connect, None),
  File "/Users/dankmank/anaconda3/lib/python3.7/site-packages/sqlalchemy/engine/base.py", line 2349, in _wrap_pool_connect
    e, dialect, self
  File "/Users/dankmank/anaconda3/lib/python3.7/site-packages/sqlalchemy/engine/base.py", line 1591, in _handle_dbapi_exception_noconnection
    sqlalchemy_exception, with_traceback=exc_info[2], from_=e
  File "/Users/dankmank/anaconda3/lib/python3.7/site-packages/sqlalchemy/util/compat.py", line 178, in raise_
    raise exception
  File "/Users/dankmank/anaconda3/lib/python3.7/site-packages/sqlalchemy/engine/base.py", line 2345, in _wrap_pool_connect
    return fn()
  File "/Users/dankmank/anaconda3/lib/python3.7/site-packages/sqlalchemy/pool/base.py", line 364, in connect
    return _ConnectionFairy._checkout(self)
  File "/Users/dankmank/anaconda3/lib/python3.7/site-packages/sqlalchemy/pool/base.py", line 778, in _checkout
    fairy = _ConnectionRecord.checkout(pool)
  File "/Users/dankmank/anaconda3/lib/python3.7/site-packages/sqlalchemy/pool/base.py", line 495, in checkout
    rec = pool._do_get()
  File "/Users/dankmank/anaconda3/lib/python3.7/site-packages/sqlalchemy/pool/impl.py", line 140, in _do_get
    self._dec_overflow()
  File "/Users/dankmank/anaconda3/lib/python3.7/site-packages/sqlalchemy/util/langhelpers.py", line 69, in __exit__
    exc_value, with_traceback=exc_tb,
  File "/Users/dankmank/anaconda3/lib/python3.7/site-packages/sqlalchemy/util/compat.py", line 178, in raise_
    raise exception
  File "/Users/dankmank/anaconda3/lib/python3.7/site-packages/sqlalchemy/pool/impl.py", line 137, in _do_get
    return self._create_connection()
  File "/Users/dankmank/anaconda3/lib/python3.7/site-packages/sqlalchemy/pool/base.py", line 309, in _create_connection
    return _ConnectionRecord(self)
  File "/Users/dankmank/anaconda3/lib/python3.7/site-packages/sqlalchemy/pool/base.py", line 440, in __init__
    self.__connect(first_connect_check=True)
  File "/Users/dankmank/anaconda3/lib/python3.7/site-packages/sqlalchemy/pool/base.py", line 661, in __connect
    pool.logger.debug("Error on connect(): %s", e)
  File "/Users/dankmank/anaconda3/lib/python3.7/site-packages/sqlalchemy/util/langhelpers.py", line 69, in __exit__
    exc_value, with_traceback=exc_tb,
  File "/Users/dankmank/anaconda3/lib/python3.7/site-packages/sqlalchemy/util/compat.py", line 178, in raise_
    raise exception
  File "/Users/dankmank/anaconda3/lib/python3.7/site-packages/sqlalchemy/pool/base.py", line 656, in __connect
    connection = pool._invoke_creator(self)
  File "/Users/dankmank/anaconda3/lib/python3.7/site-packages/sqlalchemy/engine/strategies.py", line 114, in connect
    return dialect.connect(*cargs, **cparams)
  File "/Users/dankmank/anaconda3/lib/python3.7/site-packages/sqlalchemy/engine/default.py", line 490, in connect
    return self.dbapi.connect(*cargs, **cparams)
  File "/Users/dankmank/anaconda3/lib/python3.7/site-packages/psycopg2/__init__.py", line 127, in connect
    conn = _connect(dsn, connection_factory=connection_factory, **kwasync)
sqlalchemy.exc.OperationalError: (psycopg2.OperationalError) FATAL:  too many connections for role "kdscstklqmukmb"

(Background on this error at: http://sqlalche.me/e/e3q8)
[2020-07-07 17:15:29 -0700] [19138] [ERROR] Exception in worker process
Traceback (most recent call last):
  File "/Users/dankmank/anaconda3/lib/python3.7/site-packages/sqlalchemy/engine/base.py", line 2345, in _wrap_pool_connect
    return fn()
  File "/Users/dankmank/anaconda3/lib/python3.7/site-packages/sqlalchemy/pool/base.py", line 364, in connect
    return _ConnectionFairy._checkout(self)
  File "/Users/dankmank/anaconda3/lib/python3.7/site-packages/sqlalchemy/pool/base.py", line 778, in _checkout
    fairy = _ConnectionRecord.checkout(pool)
  File "/Users/dankmank/anaconda3/lib/python3.7/site-packages/sqlalchemy/pool/base.py", line 495, in checkout
    rec = pool._do_get()
  File "/Users/dankmank/anaconda3/lib/python3.7/site-packages/sqlalchemy/pool/impl.py", line 140, in _do_get
    self._dec_overflow()
  File "/Users/dankmank/anaconda3/lib/python3.7/site-packages/sqlalchemy/util/langhelpers.py", line 69, in __exit__
    exc_value, with_traceback=exc_tb,
  File "/Users/dankmank/anaconda3/lib/python3.7/site-packages/sqlalchemy/util/compat.py", line 178, in raise_
    raise exception
  File "/Users/dankmank/anaconda3/lib/python3.7/site-packages/sqlalchemy/pool/impl.py", line 137, in _do_get
    return self._create_connection()
  File "/Users/dankmank/anaconda3/lib/python3.7/site-packages/sqlalchemy/pool/base.py", line 309, in _create_connection
    return _ConnectionRecord(self)
  File "/Users/dankmank/anaconda3/lib/python3.7/site-packages/sqlalchemy/pool/base.py", line 440, in __init__
    self.__connect(first_connect_check=True)
  File "/Users/dankmank/anaconda3/lib/python3.7/site-packages/sqlalchemy/pool/base.py", line 661, in __connect
    pool.logger.debug("Error on connect(): %s", e)
  File "/Users/dankmank/anaconda3/lib/python3.7/site-packages/sqlalchemy/util/langhelpers.py", line 69, in __exit__
    exc_value, with_traceback=exc_tb,
  File "/Users/dankmank/anaconda3/lib/python3.7/site-packages/sqlalchemy/util/compat.py", line 178, in raise_
    raise exception
  File "/Users/dankmank/anaconda3/lib/python3.7/site-packages/sqlalchemy/pool/base.py", line 656, in __connect
    connection = pool._invoke_creator(self)
  File "/Users/dankmank/anaconda3/lib/python3.7/site-packages/sqlalchemy/engine/strategies.py", line 114, in connect
    return dialect.connect(*cargs, **cparams)
  File "/Users/dankmank/anaconda3/lib/python3.7/site-packages/sqlalchemy/engine/default.py", line 490, in connect
    return self.dbapi.connect(*cargs, **cparams)
  File "/Users/dankmank/anaconda3/lib/python3.7/site-packages/psycopg2/__init__.py", line 127, in connect
    conn = _connect(dsn, connection_factory=connection_factory, **kwasync)
psycopg2.OperationalError: FATAL:  too many connections for role "kdscstklqmukmb"


The above exception was the direct cause of the following exception:

Traceback (most recent call last):
  File "/Users/dankmank/anaconda3/lib/python3.7/site-packages/gunicorn/arbiter.py", line 583, in spawn_worker
    worker.init_process()
  File "/Users/dankmank/anaconda3/lib/python3.7/site-packages/gunicorn/workers/base.py", line 129, in init_process
    self.load_wsgi()
  File "/Users/dankmank/anaconda3/lib/python3.7/site-packages/gunicorn/workers/base.py", line 138, in load_wsgi
    self.wsgi = self.app.wsgi()
  File "/Users/dankmank/anaconda3/lib/python3.7/site-packages/gunicorn/app/base.py", line 67, in wsgi
    self.callable = self.load()
  File "/Users/dankmank/anaconda3/lib/python3.7/site-packages/psiturk/experiment_server.py", line 48, in load
    return util.import_app("psiturk.experiment:app")
  File "/Users/dankmank/anaconda3/lib/python3.7/site-packages/gunicorn/util.py", line 350, in import_app
    __import__(module)
  File "/Users/dankmank/anaconda3/lib/python3.7/site-packages/psiturk/experiment.py", line 89, in <module>
    init_db()
  File "/Users/dankmank/anaconda3/lib/python3.7/site-packages/psiturk/db.py", line 37, in init_db
    Base.metadata.create_all(bind=engine)
  File "/Users/dankmank/anaconda3/lib/python3.7/site-packages/sqlalchemy/sql/schema.py", line 4465, in create_all
    ddl.SchemaGenerator, self, checkfirst=checkfirst, tables=tables
  File "/Users/dankmank/anaconda3/lib/python3.7/site-packages/sqlalchemy/engine/base.py", line 2103, in _run_visitor
    with self._optional_conn_ctx_manager(connection) as conn:
  File "/Users/dankmank/anaconda3/lib/python3.7/contextlib.py", line 112, in __enter__
    return next(self.gen)
  File "/Users/dankmank/anaconda3/lib/python3.7/site-packages/sqlalchemy/engine/base.py", line 2095, in _optional_conn_ctx_manager
    with self._contextual_connect() as conn:
  File "/Users/dankmank/anaconda3/lib/python3.7/site-packages/sqlalchemy/engine/base.py", line 2311, in _contextual_connect
    self._wrap_pool_connect(self.pool.connect, None),
  File "/Users/dankmank/anaconda3/lib/python3.7/site-packages/sqlalchemy/engine/base.py", line 2349, in _wrap_pool_connect
    e, dialect, self
  File "/Users/dankmank/anaconda3/lib/python3.7/site-packages/sqlalchemy/engine/base.py", line 1591, in _handle_dbapi_exception_noconnection
    sqlalchemy_exception, with_traceback=exc_info[2], from_=e
  File "/Users/dankmank/anaconda3/lib/python3.7/site-packages/sqlalchemy/util/compat.py", line 178, in raise_
    raise exception
  File "/Users/dankmank/anaconda3/lib/python3.7/site-packages/sqlalchemy/engine/base.py", line 2345, in _wrap_pool_connect
    return fn()
  File "/Users/dankmank/anaconda3/lib/python3.7/site-packages/sqlalchemy/pool/base.py", line 364, in connect
    return _ConnectionFairy._checkout(self)
  File "/Users/dankmank/anaconda3/lib/python3.7/site-packages/sqlalchemy/pool/base.py", line 778, in _checkout
    fairy = _ConnectionRecord.checkout(pool)
  File "/Users/dankmank/anaconda3/lib/python3.7/site-packages/sqlalchemy/pool/base.py", line 495, in checkout
    rec = pool._do_get()
  File "/Users/dankmank/anaconda3/lib/python3.7/site-packages/sqlalchemy/pool/impl.py", line 140, in _do_get
    self._dec_overflow()
  File "/Users/dankmank/anaconda3/lib/python3.7/site-packages/sqlalchemy/util/langhelpers.py", line 69, in __exit__
    exc_value, with_traceback=exc_tb,
  File "/Users/dankmank/anaconda3/lib/python3.7/site-packages/sqlalchemy/util/compat.py", line 178, in raise_
    raise exception
  File "/Users/dankmank/anaconda3/lib/python3.7/site-packages/sqlalchemy/pool/impl.py", line 137, in _do_get
    return self._create_connection()
  File "/Users/dankmank/anaconda3/lib/python3.7/site-packages/sqlalchemy/pool/base.py", line 309, in _create_connection
    return _ConnectionRecord(self)
  File "/Users/dankmank/anaconda3/lib/python3.7/site-packages/sqlalchemy/pool/base.py", line 440, in __init__
    self.__connect(first_connect_check=True)
  File "/Users/dankmank/anaconda3/lib/python3.7/site-packages/sqlalchemy/pool/base.py", line 661, in __connect
    pool.logger.debug("Error on connect(): %s", e)
  File "/Users/dankmank/anaconda3/lib/python3.7/site-packages/sqlalchemy/util/langhelpers.py", line 69, in __exit__
    exc_value, with_traceback=exc_tb,
  File "/Users/dankmank/anaconda3/lib/python3.7/site-packages/sqlalchemy/util/compat.py", line 178, in raise_
    raise exception
  File "/Users/dankmank/anaconda3/lib/python3.7/site-packages/sqlalchemy/pool/base.py", line 656, in __connect
    connection = pool._invoke_creator(self)
  File "/Users/dankmank/anaconda3/lib/python3.7/site-packages/sqlalchemy/engine/strategies.py", line 114, in connect
    return dialect.connect(*cargs, **cparams)
  File "/Users/dankmank/anaconda3/lib/python3.7/site-packages/sqlalchemy/engine/default.py", line 490, in connect
    return self.dbapi.connect(*cargs, **cparams)
  File "/Users/dankmank/anaconda3/lib/python3.7/site-packages/psycopg2/__init__.py", line 127, in connect
    conn = _connect(dsn, connection_factory=connection_factory, **kwasync)
sqlalchemy.exc.OperationalError: (psycopg2.OperationalError) FATAL:  too many connections for role "kdscstklqmukmb"

(Background on this error at: http://sqlalche.me/e/e3q8)
[2020-07-07 17:15:29 -0700] [19135] [ERROR] Exception in worker process
Traceback (most recent call last):
  File "/Users/dankmank/anaconda3/lib/python3.7/site-packages/sqlalchemy/engine/base.py", line 2345, in _wrap_pool_connect
    return fn()
  File "/Users/dankmank/anaconda3/lib/python3.7/site-packages/sqlalchemy/pool/base.py", line 364, in connect
    return _ConnectionFairy._checkout(self)
  File "/Users/dankmank/anaconda3/lib/python3.7/site-packages/sqlalchemy/pool/base.py", line 778, in _checkout
    fairy = _ConnectionRecord.checkout(pool)
  File "/Users/dankmank/anaconda3/lib/python3.7/site-packages/sqlalchemy/pool/base.py", line 495, in checkout
    rec = pool._do_get()
  File "/Users/dankmank/anaconda3/lib/python3.7/site-packages/sqlalchemy/pool/impl.py", line 140, in _do_get
    self._dec_overflow()
  File "/Users/dankmank/anaconda3/lib/python3.7/site-packages/sqlalchemy/util/langhelpers.py", line 69, in __exit__
    exc_value, with_traceback=exc_tb,
  File "/Users/dankmank/anaconda3/lib/python3.7/site-packages/sqlalchemy/util/compat.py", line 178, in raise_
    raise exception
  File "/Users/dankmank/anaconda3/lib/python3.7/site-packages/sqlalchemy/pool/impl.py", line 137, in _do_get
    return self._create_connection()
  File "/Users/dankmank/anaconda3/lib/python3.7/site-packages/sqlalchemy/pool/base.py", line 309, in _create_connection
    return _ConnectionRecord(self)
  File "/Users/dankmank/anaconda3/lib/python3.7/site-packages/sqlalchemy/pool/base.py", line 440, in __init__
    self.__connect(first_connect_check=True)
  File "/Users/dankmank/anaconda3/lib/python3.7/site-packages/sqlalchemy/pool/base.py", line 661, in __connect
    pool.logger.debug("Error on connect(): %s", e)
  File "/Users/dankmank/anaconda3/lib/python3.7/site-packages/sqlalchemy/util/langhelpers.py", line 69, in __exit__
    exc_value, with_traceback=exc_tb,
  File "/Users/dankmank/anaconda3/lib/python3.7/site-packages/sqlalchemy/util/compat.py", line 178, in raise_
    raise exception
  File "/Users/dankmank/anaconda3/lib/python3.7/site-packages/sqlalchemy/pool/base.py", line 656, in __connect
    connection = pool._invoke_creator(self)
  File "/Users/dankmank/anaconda3/lib/python3.7/site-packages/sqlalchemy/engine/strategies.py", line 114, in connect
    return dialect.connect(*cargs, **cparams)
  File "/Users/dankmank/anaconda3/lib/python3.7/site-packages/sqlalchemy/engine/default.py", line 490, in connect
    return self.dbapi.connect(*cargs, **cparams)
  File "/Users/dankmank/anaconda3/lib/python3.7/site-packages/psycopg2/__init__.py", line 127, in connect
    conn = _connect(dsn, connection_factory=connection_factory, **kwasync)
psycopg2.OperationalError: FATAL:  too many connections for role "kdscstklqmukmb"


The above exception was the direct cause of the following exception:

Traceback (most recent call last):
  File "/Users/dankmank/anaconda3/lib/python3.7/site-packages/gunicorn/arbiter.py", line 583, in spawn_worker
    worker.init_process()
  File "/Users/dankmank/anaconda3/lib/python3.7/site-packages/gunicorn/workers/base.py", line 129, in init_process
    self.load_wsgi()
  File "/Users/dankmank/anaconda3/lib/python3.7/site-packages/gunicorn/workers/base.py", line 138, in load_wsgi
    self.wsgi = self.app.wsgi()
  File "/Users/dankmank/anaconda3/lib/python3.7/site-packages/gunicorn/app/base.py", line 67, in wsgi
    self.callable = self.load()
  File "/Users/dankmank/anaconda3/lib/python3.7/site-packages/psiturk/experiment_server.py", line 48, in load
    return util.import_app("psiturk.experiment:app")
  File "/Users/dankmank/anaconda3/lib/python3.7/site-packages/gunicorn/util.py", line 350, in import_app
    __import__(module)
  File "/Users/dankmank/anaconda3/lib/python3.7/site-packages/psiturk/experiment.py", line 89, in <module>
    init_db()
  File "/Users/dankmank/anaconda3/lib/python3.7/site-packages/psiturk/db.py", line 37, in init_db
    Base.metadata.create_all(bind=engine)
  File "/Users/dankmank/anaconda3/lib/python3.7/site-packages/sqlalchemy/sql/schema.py", line 4465, in create_all
    ddl.SchemaGenerator, self, checkfirst=checkfirst, tables=tables
  File "/Users/dankmank/anaconda3/lib/python3.7/site-packages/sqlalchemy/engine/base.py", line 2103, in _run_visitor
    with self._optional_conn_ctx_manager(connection) as conn:
  File "/Users/dankmank/anaconda3/lib/python3.7/contextlib.py", line 112, in __enter__
    return next(self.gen)
  File "/Users/dankmank/anaconda3/lib/python3.7/site-packages/sqlalchemy/engine/base.py", line 2095, in _optional_conn_ctx_manager
    with self._contextual_connect() as conn:
  File "/Users/dankmank/anaconda3/lib/python3.7/site-packages/sqlalchemy/engine/base.py", line 2311, in _contextual_connect
    self._wrap_pool_connect(self.pool.connect, None),
  File "/Users/dankmank/anaconda3/lib/python3.7/site-packages/sqlalchemy/engine/base.py", line 2349, in _wrap_pool_connect
    e, dialect, self
  File "/Users/dankmank/anaconda3/lib/python3.7/site-packages/sqlalchemy/engine/base.py", line 1591, in _handle_dbapi_exception_noconnection
    sqlalchemy_exception, with_traceback=exc_info[2], from_=e
  File "/Users/dankmank/anaconda3/lib/python3.7/site-packages/sqlalchemy/util/compat.py", line 178, in raise_
    raise exception
  File "/Users/dankmank/anaconda3/lib/python3.7/site-packages/sqlalchemy/engine/base.py", line 2345, in _wrap_pool_connect
    return fn()
  File "/Users/dankmank/anaconda3/lib/python3.7/site-packages/sqlalchemy/pool/base.py", line 364, in connect
    return _ConnectionFairy._checkout(self)
  File "/Users/dankmank/anaconda3/lib/python3.7/site-packages/sqlalchemy/pool/base.py", line 778, in _checkout
    fairy = _ConnectionRecord.checkout(pool)
  File "/Users/dankmank/anaconda3/lib/python3.7/site-packages/sqlalchemy/pool/base.py", line 495, in checkout
    rec = pool._do_get()
  File "/Users/dankmank/anaconda3/lib/python3.7/site-packages/sqlalchemy/pool/impl.py", line 140, in _do_get
    self._dec_overflow()
  File "/Users/dankmank/anaconda3/lib/python3.7/site-packages/sqlalchemy/util/langhelpers.py", line 69, in __exit__
    exc_value, with_traceback=exc_tb,
  File "/Users/dankmank/anaconda3/lib/python3.7/site-packages/sqlalchemy/util/compat.py", line 178, in raise_
    raise exception
  File "/Users/dankmank/anaconda3/lib/python3.7/site-packages/sqlalchemy/pool/impl.py", line 137, in _do_get
    return self._create_connection()
  File "/Users/dankmank/anaconda3/lib/python3.7/site-packages/sqlalchemy/pool/base.py", line 309, in _create_connection
    return _ConnectionRecord(self)
  File "/Users/dankmank/anaconda3/lib/python3.7/site-packages/sqlalchemy/pool/base.py", line 440, in __init__
    self.__connect(first_connect_check=True)
  File "/Users/dankmank/anaconda3/lib/python3.7/site-packages/sqlalchemy/pool/base.py", line 661, in __connect
    pool.logger.debug("Error on connect(): %s", e)
  File "/Users/dankmank/anaconda3/lib/python3.7/site-packages/sqlalchemy/util/langhelpers.py", line 69, in __exit__
    exc_value, with_traceback=exc_tb,
  File "/Users/dankmank/anaconda3/lib/python3.7/site-packages/sqlalchemy/util/compat.py", line 178, in raise_
    raise exception
  File "/Users/dankmank/anaconda3/lib/python3.7/site-packages/sqlalchemy/pool/base.py", line 656, in __connect
    connection = pool._invoke_creator(self)
  File "/Users/dankmank/anaconda3/lib/python3.7/site-packages/sqlalchemy/engine/strategies.py", line 114, in connect
    return dialect.connect(*cargs, **cparams)
  File "/Users/dankmank/anaconda3/lib/python3.7/site-packages/sqlalchemy/engine/default.py", line 490, in connect
    return self.dbapi.connect(*cargs, **cparams)
  File "/Users/dankmank/anaconda3/lib/python3.7/site-packages/psycopg2/__init__.py", line 127, in connect
    conn = _connect(dsn, connection_factory=connection_factory, **kwasync)
sqlalchemy.exc.OperationalError: (psycopg2.OperationalError) FATAL:  too many connections for role "kdscstklqmukmb"

(Background on this error at: http://sqlalche.me/e/e3q8)
[2020-07-07 17:15:29 -0700] [19137] [ERROR] Exception in worker process
Traceback (most recent call last):
  File "/Users/dankmank/anaconda3/lib/python3.7/site-packages/sqlalchemy/engine/base.py", line 2345, in _wrap_pool_connect
    return fn()
  File "/Users/dankmank/anaconda3/lib/python3.7/site-packages/sqlalchemy/pool/base.py", line 364, in connect
    return _ConnectionFairy._checkout(self)
  File "/Users/dankmank/anaconda3/lib/python3.7/site-packages/sqlalchemy/pool/base.py", line 778, in _checkout
    fairy = _ConnectionRecord.checkout(pool)
  File "/Users/dankmank/anaconda3/lib/python3.7/site-packages/sqlalchemy/pool/base.py", line 495, in checkout
    rec = pool._do_get()
  File "/Users/dankmank/anaconda3/lib/python3.7/site-packages/sqlalchemy/pool/impl.py", line 140, in _do_get
    self._dec_overflow()
  File "/Users/dankmank/anaconda3/lib/python3.7/site-packages/sqlalchemy/util/langhelpers.py", line 69, in __exit__
    exc_value, with_traceback=exc_tb,
  File "/Users/dankmank/anaconda3/lib/python3.7/site-packages/sqlalchemy/util/compat.py", line 178, in raise_
    raise exception
  File "/Users/dankmank/anaconda3/lib/python3.7/site-packages/sqlalchemy/pool/impl.py", line 137, in _do_get
    return self._create_connection()
  File "/Users/dankmank/anaconda3/lib/python3.7/site-packages/sqlalchemy/pool/base.py", line 309, in _create_connection
    return _ConnectionRecord(self)
  File "/Users/dankmank/anaconda3/lib/python3.7/site-packages/sqlalchemy/pool/base.py", line 440, in __init__
    self.__connect(first_connect_check=True)
  File "/Users/dankmank/anaconda3/lib/python3.7/site-packages/sqlalchemy/pool/base.py", line 661, in __connect
    pool.logger.debug("Error on connect(): %s", e)
  File "/Users/dankmank/anaconda3/lib/python3.7/site-packages/sqlalchemy/util/langhelpers.py", line 69, in __exit__
    exc_value, with_traceback=exc_tb,
  File "/Users/dankmank/anaconda3/lib/python3.7/site-packages/sqlalchemy/util/compat.py", line 178, in raise_
    raise exception
  File "/Users/dankmank/anaconda3/lib/python3.7/site-packages/sqlalchemy/pool/base.py", line 656, in __connect
    connection = pool._invoke_creator(self)
  File "/Users/dankmank/anaconda3/lib/python3.7/site-packages/sqlalchemy/engine/strategies.py", line 114, in connect
    return dialect.connect(*cargs, **cparams)
  File "/Users/dankmank/anaconda3/lib/python3.7/site-packages/sqlalchemy/engine/default.py", line 490, in connect
    return self.dbapi.connect(*cargs, **cparams)
  File "/Users/dankmank/anaconda3/lib/python3.7/site-packages/psycopg2/__init__.py", line 127, in connect
    conn = _connect(dsn, connection_factory=connection_factory, **kwasync)
psycopg2.OperationalError: FATAL:  too many connections for role "kdscstklqmukmb"


The above exception was the direct cause of the following exception:

Traceback (most recent call last):
  File "/Users/dankmank/anaconda3/lib/python3.7/site-packages/gunicorn/arbiter.py", line 583, in spawn_worker
    worker.init_process()
  File "/Users/dankmank/anaconda3/lib/python3.7/site-packages/gunicorn/workers/base.py", line 129, in init_process
    self.load_wsgi()
  File "/Users/dankmank/anaconda3/lib/python3.7/site-packages/gunicorn/workers/base.py", line 138, in load_wsgi
    self.wsgi = self.app.wsgi()
  File "/Users/dankmank/anaconda3/lib/python3.7/site-packages/gunicorn/app/base.py", line 67, in wsgi
    self.callable = self.load()
  File "/Users/dankmank/anaconda3/lib/python3.7/site-packages/psiturk/experiment_server.py", line 48, in load
    return util.import_app("psiturk.experiment:app")
  File "/Users/dankmank/anaconda3/lib/python3.7/site-packages/gunicorn/util.py", line 350, in import_app
    __import__(module)
  File "/Users/dankmank/anaconda3/lib/python3.7/site-packages/psiturk/experiment.py", line 89, in <module>
    init_db()
  File "/Users/dankmank/anaconda3/lib/python3.7/site-packages/psiturk/db.py", line 37, in init_db
    Base.metadata.create_all(bind=engine)
  File "/Users/dankmank/anaconda3/lib/python3.7/site-packages/sqlalchemy/sql/schema.py", line 4465, in create_all
    ddl.SchemaGenerator, self, checkfirst=checkfirst, tables=tables
  File "/Users/dankmank/anaconda3/lib/python3.7/site-packages/sqlalchemy/engine/base.py", line 2103, in _run_visitor
    with self._optional_conn_ctx_manager(connection) as conn:
  File "/Users/dankmank/anaconda3/lib/python3.7/contextlib.py", line 112, in __enter__
    return next(self.gen)
  File "/Users/dankmank/anaconda3/lib/python3.7/site-packages/sqlalchemy/engine/base.py", line 2095, in _optional_conn_ctx_manager
    with self._contextual_connect() as conn:
  File "/Users/dankmank/anaconda3/lib/python3.7/site-packages/sqlalchemy/engine/base.py", line 2311, in _contextual_connect
    self._wrap_pool_connect(self.pool.connect, None),
  File "/Users/dankmank/anaconda3/lib/python3.7/site-packages/sqlalchemy/engine/base.py", line 2349, in _wrap_pool_connect
    e, dialect, self
  File "/Users/dankmank/anaconda3/lib/python3.7/site-packages/sqlalchemy/engine/base.py", line 1591, in _handle_dbapi_exception_noconnection
    sqlalchemy_exception, with_traceback=exc_info[2], from_=e
  File "/Users/dankmank/anaconda3/lib/python3.7/site-packages/sqlalchemy/util/compat.py", line 178, in raise_
    raise exception
  File "/Users/dankmank/anaconda3/lib/python3.7/site-packages/sqlalchemy/engine/base.py", line 2345, in _wrap_pool_connect
    return fn()
  File "/Users/dankmank/anaconda3/lib/python3.7/site-packages/sqlalchemy/pool/base.py", line 364, in connect
    return _ConnectionFairy._checkout(self)
  File "/Users/dankmank/anaconda3/lib/python3.7/site-packages/sqlalchemy/pool/base.py", line 778, in _checkout
    fairy = _ConnectionRecord.checkout(pool)
  File "/Users/dankmank/anaconda3/lib/python3.7/site-packages/sqlalchemy/pool/base.py", line 495, in checkout
    rec = pool._do_get()
  File "/Users/dankmank/anaconda3/lib/python3.7/site-packages/sqlalchemy/pool/impl.py", line 140, in _do_get
    self._dec_overflow()
  File "/Users/dankmank/anaconda3/lib/python3.7/site-packages/sqlalchemy/util/langhelpers.py", line 69, in __exit__
    exc_value, with_traceback=exc_tb,
  File "/Users/dankmank/anaconda3/lib/python3.7/site-packages/sqlalchemy/util/compat.py", line 178, in raise_
    raise exception
  File "/Users/dankmank/anaconda3/lib/python3.7/site-packages/sqlalchemy/pool/impl.py", line 137, in _do_get
    return self._create_connection()
  File "/Users/dankmank/anaconda3/lib/python3.7/site-packages/sqlalchemy/pool/base.py", line 309, in _create_connection
    return _ConnectionRecord(self)
  File "/Users/dankmank/anaconda3/lib/python3.7/site-packages/sqlalchemy/pool/base.py", line 440, in __init__
    self.__connect(first_connect_check=True)
  File "/Users/dankmank/anaconda3/lib/python3.7/site-packages/sqlalchemy/pool/base.py", line 661, in __connect
    pool.logger.debug("Error on connect(): %s", e)
  File "/Users/dankmank/anaconda3/lib/python3.7/site-packages/sqlalchemy/util/langhelpers.py", line 69, in __exit__
    exc_value, with_traceback=exc_tb,
  File "/Users/dankmank/anaconda3/lib/python3.7/site-packages/sqlalchemy/util/compat.py", line 178, in raise_
    raise exception
  File "/Users/dankmank/anaconda3/lib/python3.7/site-packages/sqlalchemy/pool/base.py", line 656, in __connect
    connection = pool._invoke_creator(self)
  File "/Users/dankmank/anaconda3/lib/python3.7/site-packages/sqlalchemy/engine/strategies.py", line 114, in connect
    return dialect.connect(*cargs, **cparams)
  File "/Users/dankmank/anaconda3/lib/python3.7/site-packages/sqlalchemy/engine/default.py", line 490, in connect
    return self.dbapi.connect(*cargs, **cparams)
  File "/Users/dankmank/anaconda3/lib/python3.7/site-packages/psycopg2/__init__.py", line 127, in connect
    conn = _connect(dsn, connection_factory=connection_factory, **kwasync)
sqlalchemy.exc.OperationalError: (psycopg2.OperationalError) FATAL:  too many connections for role "kdscstklqmukmb"

(Background on this error at: http://sqlalche.me/e/e3q8)
[2020-07-07 17:15:29 -0700] [19139] [ERROR] Exception in worker process
Traceback (most recent call last):
  File "/Users/dankmank/anaconda3/lib/python3.7/site-packages/sqlalchemy/engine/base.py", line 2345, in _wrap_pool_connect
    return fn()
  File "/Users/dankmank/anaconda3/lib/python3.7/site-packages/sqlalchemy/pool/base.py", line 364, in connect
    return _ConnectionFairy._checkout(self)
  File "/Users/dankmank/anaconda3/lib/python3.7/site-packages/sqlalchemy/pool/base.py", line 778, in _checkout
    fairy = _ConnectionRecord.checkout(pool)
  File "/Users/dankmank/anaconda3/lib/python3.7/site-packages/sqlalchemy/pool/base.py", line 495, in checkout
    rec = pool._do_get()
  File "/Users/dankmank/anaconda3/lib/python3.7/site-packages/sqlalchemy/pool/impl.py", line 140, in _do_get
    self._dec_overflow()
  File "/Users/dankmank/anaconda3/lib/python3.7/site-packages/sqlalchemy/util/langhelpers.py", line 69, in __exit__
    exc_value, with_traceback=exc_tb,
  File "/Users/dankmank/anaconda3/lib/python3.7/site-packages/sqlalchemy/util/compat.py", line 178, in raise_
    raise exception
  File "/Users/dankmank/anaconda3/lib/python3.7/site-packages/sqlalchemy/pool/impl.py", line 137, in _do_get
    return self._create_connection()
  File "/Users/dankmank/anaconda3/lib/python3.7/site-packages/sqlalchemy/pool/base.py", line 309, in _create_connection
    return _ConnectionRecord(self)
  File "/Users/dankmank/anaconda3/lib/python3.7/site-packages/sqlalchemy/pool/base.py", line 440, in __init__
    self.__connect(first_connect_check=True)
  File "/Users/dankmank/anaconda3/lib/python3.7/site-packages/sqlalchemy/pool/base.py", line 661, in __connect
    pool.logger.debug("Error on connect(): %s", e)
  File "/Users/dankmank/anaconda3/lib/python3.7/site-packages/sqlalchemy/util/langhelpers.py", line 69, in __exit__
    exc_value, with_traceback=exc_tb,
  File "/Users/dankmank/anaconda3/lib/python3.7/site-packages/sqlalchemy/util/compat.py", line 178, in raise_
    raise exception
  File "/Users/dankmank/anaconda3/lib/python3.7/site-packages/sqlalchemy/pool/base.py", line 656, in __connect
    connection = pool._invoke_creator(self)
  File "/Users/dankmank/anaconda3/lib/python3.7/site-packages/sqlalchemy/engine/strategies.py", line 114, in connect
    return dialect.connect(*cargs, **cparams)
  File "/Users/dankmank/anaconda3/lib/python3.7/site-packages/sqlalchemy/engine/default.py", line 490, in connect
    return self.dbapi.connect(*cargs, **cparams)
  File "/Users/dankmank/anaconda3/lib/python3.7/site-packages/psycopg2/__init__.py", line 127, in connect
    conn = _connect(dsn, connection_factory=connection_factory, **kwasync)
psycopg2.OperationalError: FATAL:  too many connections for role "kdscstklqmukmb"


The above exception was the direct cause of the following exception:

Traceback (most recent call last):
  File "/Users/dankmank/anaconda3/lib/python3.7/site-packages/gunicorn/arbiter.py", line 583, in spawn_worker
    worker.init_process()
  File "/Users/dankmank/anaconda3/lib/python3.7/site-packages/gunicorn/workers/base.py", line 129, in init_process
    self.load_wsgi()
  File "/Users/dankmank/anaconda3/lib/python3.7/site-packages/gunicorn/workers/base.py", line 138, in load_wsgi
    self.wsgi = self.app.wsgi()
  File "/Users/dankmank/anaconda3/lib/python3.7/site-packages/gunicorn/app/base.py", line 67, in wsgi
    self.callable = self.load()
  File "/Users/dankmank/anaconda3/lib/python3.7/site-packages/psiturk/experiment_server.py", line 48, in load
    return util.import_app("psiturk.experiment:app")
  File "/Users/dankmank/anaconda3/lib/python3.7/site-packages/gunicorn/util.py", line 350, in import_app
    __import__(module)
  File "/Users/dankmank/anaconda3/lib/python3.7/site-packages/psiturk/experiment.py", line 89, in <module>
    init_db()
  File "/Users/dankmank/anaconda3/lib/python3.7/site-packages/psiturk/db.py", line 37, in init_db
    Base.metadata.create_all(bind=engine)
  File "/Users/dankmank/anaconda3/lib/python3.7/site-packages/sqlalchemy/sql/schema.py", line 4465, in create_all
    ddl.SchemaGenerator, self, checkfirst=checkfirst, tables=tables
  File "/Users/dankmank/anaconda3/lib/python3.7/site-packages/sqlalchemy/engine/base.py", line 2103, in _run_visitor
    with self._optional_conn_ctx_manager(connection) as conn:
  File "/Users/dankmank/anaconda3/lib/python3.7/contextlib.py", line 112, in __enter__
    return next(self.gen)
  File "/Users/dankmank/anaconda3/lib/python3.7/site-packages/sqlalchemy/engine/base.py", line 2095, in _optional_conn_ctx_manager
    with self._contextual_connect() as conn:
  File "/Users/dankmank/anaconda3/lib/python3.7/site-packages/sqlalchemy/engine/base.py", line 2311, in _contextual_connect
    self._wrap_pool_connect(self.pool.connect, None),
  File "/Users/dankmank/anaconda3/lib/python3.7/site-packages/sqlalchemy/engine/base.py", line 2349, in _wrap_pool_connect
    e, dialect, self
  File "/Users/dankmank/anaconda3/lib/python3.7/site-packages/sqlalchemy/engine/base.py", line 1591, in _handle_dbapi_exception_noconnection
    sqlalchemy_exception, with_traceback=exc_info[2], from_=e
  File "/Users/dankmank/anaconda3/lib/python3.7/site-packages/sqlalchemy/util/compat.py", line 178, in raise_
    raise exception
  File "/Users/dankmank/anaconda3/lib/python3.7/site-packages/sqlalchemy/engine/base.py", line 2345, in _wrap_pool_connect
    return fn()
  File "/Users/dankmank/anaconda3/lib/python3.7/site-packages/sqlalchemy/pool/base.py", line 364, in connect
    return _ConnectionFairy._checkout(self)
  File "/Users/dankmank/anaconda3/lib/python3.7/site-packages/sqlalchemy/pool/base.py", line 778, in _checkout
    fairy = _ConnectionRecord.checkout(pool)
  File "/Users/dankmank/anaconda3/lib/python3.7/site-packages/sqlalchemy/pool/base.py", line 495, in checkout
    rec = pool._do_get()
  File "/Users/dankmank/anaconda3/lib/python3.7/site-packages/sqlalchemy/pool/impl.py", line 140, in _do_get
    self._dec_overflow()
  File "/Users/dankmank/anaconda3/lib/python3.7/site-packages/sqlalchemy/util/langhelpers.py", line 69, in __exit__
    exc_value, with_traceback=exc_tb,
  File "/Users/dankmank/anaconda3/lib/python3.7/site-packages/sqlalchemy/util/compat.py", line 178, in raise_
    raise exception
  File "/Users/dankmank/anaconda3/lib/python3.7/site-packages/sqlalchemy/pool/impl.py", line 137, in _do_get
    return self._create_connection()
  File "/Users/dankmank/anaconda3/lib/python3.7/site-packages/sqlalchemy/pool/base.py", line 309, in _create_connection
    return _ConnectionRecord(self)
  File "/Users/dankmank/anaconda3/lib/python3.7/site-packages/sqlalchemy/pool/base.py", line 440, in __init__
    self.__connect(first_connect_check=True)
  File "/Users/dankmank/anaconda3/lib/python3.7/site-packages/sqlalchemy/pool/base.py", line 661, in __connect
    pool.logger.debug("Error on connect(): %s", e)
  File "/Users/dankmank/anaconda3/lib/python3.7/site-packages/sqlalchemy/util/langhelpers.py", line 69, in __exit__
    exc_value, with_traceback=exc_tb,
  File "/Users/dankmank/anaconda3/lib/python3.7/site-packages/sqlalchemy/util/compat.py", line 178, in raise_
    raise exception
  File "/Users/dankmank/anaconda3/lib/python3.7/site-packages/sqlalchemy/pool/base.py", line 656, in __connect
    connection = pool._invoke_creator(self)
  File "/Users/dankmank/anaconda3/lib/python3.7/site-packages/sqlalchemy/engine/strategies.py", line 114, in connect
    return dialect.connect(*cargs, **cparams)
  File "/Users/dankmank/anaconda3/lib/python3.7/site-packages/sqlalchemy/engine/default.py", line 490, in connect
    return self.dbapi.connect(*cargs, **cparams)
  File "/Users/dankmank/anaconda3/lib/python3.7/site-packages/psycopg2/__init__.py", line 127, in connect
    conn = _connect(dsn, connection_factory=connection_factory, **kwasync)
sqlalchemy.exc.OperationalError: (psycopg2.OperationalError) FATAL:  too many connections for role "kdscstklqmukmb"

(Background on this error at: http://sqlalche.me/e/e3q8)
[2020-07-07 17:15:29 -0700] [19141] [ERROR] Exception in worker process
Traceback (most recent call last):
  File "/Users/dankmank/anaconda3/lib/python3.7/site-packages/sqlalchemy/engine/base.py", line 2345, in _wrap_pool_connect
    return fn()
  File "/Users/dankmank/anaconda3/lib/python3.7/site-packages/sqlalchemy/pool/base.py", line 364, in connect
    return _ConnectionFairy._checkout(self)
  File "/Users/dankmank/anaconda3/lib/python3.7/site-packages/sqlalchemy/pool/base.py", line 778, in _checkout
    fairy = _ConnectionRecord.checkout(pool)
  File "/Users/dankmank/anaconda3/lib/python3.7/site-packages/sqlalchemy/pool/base.py", line 495, in checkout
    rec = pool._do_get()
  File "/Users/dankmank/anaconda3/lib/python3.7/site-packages/sqlalchemy/pool/impl.py", line 140, in _do_get
    self._dec_overflow()
  File "/Users/dankmank/anaconda3/lib/python3.7/site-packages/sqlalchemy/util/langhelpers.py", line 69, in __exit__
    exc_value, with_traceback=exc_tb,
  File "/Users/dankmank/anaconda3/lib/python3.7/site-packages/sqlalchemy/util/compat.py", line 178, in raise_
    raise exception
  File "/Users/dankmank/anaconda3/lib/python3.7/site-packages/sqlalchemy/pool/impl.py", line 137, in _do_get
    return self._create_connection()
  File "/Users/dankmank/anaconda3/lib/python3.7/site-packages/sqlalchemy/pool/base.py", line 309, in _create_connection
    return _ConnectionRecord(self)
  File "/Users/dankmank/anaconda3/lib/python3.7/site-packages/sqlalchemy/pool/base.py", line 440, in __init__
    self.__connect(first_connect_check=True)
  File "/Users/dankmank/anaconda3/lib/python3.7/site-packages/sqlalchemy/pool/base.py", line 661, in __connect
    pool.logger.debug("Error on connect(): %s", e)
  File "/Users/dankmank/anaconda3/lib/python3.7/site-packages/sqlalchemy/util/langhelpers.py", line 69, in __exit__
    exc_value, with_traceback=exc_tb,
  File "/Users/dankmank/anaconda3/lib/python3.7/site-packages/sqlalchemy/util/compat.py", line 178, in raise_
    raise exception
  File "/Users/dankmank/anaconda3/lib/python3.7/site-packages/sqlalchemy/pool/base.py", line 656, in __connect
    connection = pool._invoke_creator(self)
  File "/Users/dankmank/anaconda3/lib/python3.7/site-packages/sqlalchemy/engine/strategies.py", line 114, in connect
    return dialect.connect(*cargs, **cparams)
  File "/Users/dankmank/anaconda3/lib/python3.7/site-packages/sqlalchemy/engine/default.py", line 490, in connect
    return self.dbapi.connect(*cargs, **cparams)
  File "/Users/dankmank/anaconda3/lib/python3.7/site-packages/psycopg2/__init__.py", line 127, in connect
    conn = _connect(dsn, connection_factory=connection_factory, **kwasync)
psycopg2.OperationalError: FATAL:  too many connections for role "kdscstklqmukmb"


The above exception was the direct cause of the following exception:

Traceback (most recent call last):
  File "/Users/dankmank/anaconda3/lib/python3.7/site-packages/gunicorn/arbiter.py", line 583, in spawn_worker
    worker.init_process()
  File "/Users/dankmank/anaconda3/lib/python3.7/site-packages/gunicorn/workers/base.py", line 129, in init_process
    self.load_wsgi()
  File "/Users/dankmank/anaconda3/lib/python3.7/site-packages/gunicorn/workers/base.py", line 138, in load_wsgi
    self.wsgi = self.app.wsgi()
  File "/Users/dankmank/anaconda3/lib/python3.7/site-packages/gunicorn/app/base.py", line 67, in wsgi
    self.callable = self.load()
  File "/Users/dankmank/anaconda3/lib/python3.7/site-packages/psiturk/experiment_server.py", line 48, in load
    return util.import_app("psiturk.experiment:app")
  File "/Users/dankmank/anaconda3/lib/python3.7/site-packages/gunicorn/util.py", line 350, in import_app
    __import__(module)
  File "/Users/dankmank/anaconda3/lib/python3.7/site-packages/psiturk/experiment.py", line 89, in <module>
    init_db()
  File "/Users/dankmank/anaconda3/lib/python3.7/site-packages/psiturk/db.py", line 37, in init_db
    Base.metadata.create_all(bind=engine)
  File "/Users/dankmank/anaconda3/lib/python3.7/site-packages/sqlalchemy/sql/schema.py", line 4465, in create_all
    ddl.SchemaGenerator, self, checkfirst=checkfirst, tables=tables
  File "/Users/dankmank/anaconda3/lib/python3.7/site-packages/sqlalchemy/engine/base.py", line 2103, in _run_visitor
    with self._optional_conn_ctx_manager(connection) as conn:
  File "/Users/dankmank/anaconda3/lib/python3.7/contextlib.py", line 112, in __enter__
    return next(self.gen)
  File "/Users/dankmank/anaconda3/lib/python3.7/site-packages/sqlalchemy/engine/base.py", line 2095, in _optional_conn_ctx_manager
    with self._contextual_connect() as conn:
  File "/Users/dankmank/anaconda3/lib/python3.7/site-packages/sqlalchemy/engine/base.py", line 2311, in _contextual_connect
    self._wrap_pool_connect(self.pool.connect, None),
  File "/Users/dankmank/anaconda3/lib/python3.7/site-packages/sqlalchemy/engine/base.py", line 2349, in _wrap_pool_connect
    e, dialect, self
  File "/Users/dankmank/anaconda3/lib/python3.7/site-packages/sqlalchemy/engine/base.py", line 1591, in _handle_dbapi_exception_noconnection
    sqlalchemy_exception, with_traceback=exc_info[2], from_=e
  File "/Users/dankmank/anaconda3/lib/python3.7/site-packages/sqlalchemy/util/compat.py", line 178, in raise_
    raise exception
  File "/Users/dankmank/anaconda3/lib/python3.7/site-packages/sqlalchemy/engine/base.py", line 2345, in _wrap_pool_connect
    return fn()
  File "/Users/dankmank/anaconda3/lib/python3.7/site-packages/sqlalchemy/pool/base.py", line 364, in connect
    return _ConnectionFairy._checkout(self)
  File "/Users/dankmank/anaconda3/lib/python3.7/site-packages/sqlalchemy/pool/base.py", line 778, in _checkout
    fairy = _ConnectionRecord.checkout(pool)
  File "/Users/dankmank/anaconda3/lib/python3.7/site-packages/sqlalchemy/pool/base.py", line 495, in checkout
    rec = pool._do_get()
  File "/Users/dankmank/anaconda3/lib/python3.7/site-packages/sqlalchemy/pool/impl.py", line 140, in _do_get
    self._dec_overflow()
  File "/Users/dankmank/anaconda3/lib/python3.7/site-packages/sqlalchemy/util/langhelpers.py", line 69, in __exit__
    exc_value, with_traceback=exc_tb,
  File "/Users/dankmank/anaconda3/lib/python3.7/site-packages/sqlalchemy/util/compat.py", line 178, in raise_
    raise exception
  File "/Users/dankmank/anaconda3/lib/python3.7/site-packages/sqlalchemy/pool/impl.py", line 137, in _do_get
    return self._create_connection()
  File "/Users/dankmank/anaconda3/lib/python3.7/site-packages/sqlalchemy/pool/base.py", line 309, in _create_connection
    return _ConnectionRecord(self)
  File "/Users/dankmank/anaconda3/lib/python3.7/site-packages/sqlalchemy/pool/base.py", line 440, in __init__
    self.__connect(first_connect_check=True)
  File "/Users/dankmank/anaconda3/lib/python3.7/site-packages/sqlalchemy/pool/base.py", line 661, in __connect
    pool.logger.debug("Error on connect(): %s", e)
  File "/Users/dankmank/anaconda3/lib/python3.7/site-packages/sqlalchemy/util/langhelpers.py", line 69, in __exit__
    exc_value, with_traceback=exc_tb,
  File "/Users/dankmank/anaconda3/lib/python3.7/site-packages/sqlalchemy/util/compat.py", line 178, in raise_
    raise exception
  File "/Users/dankmank/anaconda3/lib/python3.7/site-packages/sqlalchemy/pool/base.py", line 656, in __connect
    connection = pool._invoke_creator(self)
  File "/Users/dankmank/anaconda3/lib/python3.7/site-packages/sqlalchemy/engine/strategies.py", line 114, in connect
    return dialect.connect(*cargs, **cparams)
  File "/Users/dankmank/anaconda3/lib/python3.7/site-packages/sqlalchemy/engine/default.py", line 490, in connect
    return self.dbapi.connect(*cargs, **cparams)
  File "/Users/dankmank/anaconda3/lib/python3.7/site-packages/psycopg2/__init__.py", line 127, in connect
    conn = _connect(dsn, connection_factory=connection_factory, **kwasync)
sqlalchemy.exc.OperationalError: (psycopg2.OperationalError) FATAL:  too many connections for role "kdscstklqmukmb"

(Background on this error at: http://sqlalche.me/e/e3q8)
[2020-07-07 17:15:29 -0700] [19140] [ERROR] Exception in worker process
Traceback (most recent call last):
  File "/Users/dankmank/anaconda3/lib/python3.7/site-packages/sqlalchemy/engine/base.py", line 2345, in _wrap_pool_connect
    return fn()
  File "/Users/dankmank/anaconda3/lib/python3.7/site-packages/sqlalchemy/pool/base.py", line 364, in connect
    return _ConnectionFairy._checkout(self)
  File "/Users/dankmank/anaconda3/lib/python3.7/site-packages/sqlalchemy/pool/base.py", line 778, in _checkout
    fairy = _ConnectionRecord.checkout(pool)
  File "/Users/dankmank/anaconda3/lib/python3.7/site-packages/sqlalchemy/pool/base.py", line 495, in checkout
    rec = pool._do_get()
  File "/Users/dankmank/anaconda3/lib/python3.7/site-packages/sqlalchemy/pool/impl.py", line 140, in _do_get
    self._dec_overflow()
  File "/Users/dankmank/anaconda3/lib/python3.7/site-packages/sqlalchemy/util/langhelpers.py", line 69, in __exit__
    exc_value, with_traceback=exc_tb,
  File "/Users/dankmank/anaconda3/lib/python3.7/site-packages/sqlalchemy/util/compat.py", line 178, in raise_
    raise exception
  File "/Users/dankmank/anaconda3/lib/python3.7/site-packages/sqlalchemy/pool/impl.py", line 137, in _do_get
    return self._create_connection()
  File "/Users/dankmank/anaconda3/lib/python3.7/site-packages/sqlalchemy/pool/base.py", line 309, in _create_connection
    return _ConnectionRecord(self)
  File "/Users/dankmank/anaconda3/lib/python3.7/site-packages/sqlalchemy/pool/base.py", line 440, in __init__
    self.__connect(first_connect_check=True)
  File "/Users/dankmank/anaconda3/lib/python3.7/site-packages/sqlalchemy/pool/base.py", line 661, in __connect
    pool.logger.debug("Error on connect(): %s", e)
  File "/Users/dankmank/anaconda3/lib/python3.7/site-packages/sqlalchemy/util/langhelpers.py", line 69, in __exit__
    exc_value, with_traceback=exc_tb,
  File "/Users/dankmank/anaconda3/lib/python3.7/site-packages/sqlalchemy/util/compat.py", line 178, in raise_
    raise exception
  File "/Users/dankmank/anaconda3/lib/python3.7/site-packages/sqlalchemy/pool/base.py", line 656, in __connect
    connection = pool._invoke_creator(self)
  File "/Users/dankmank/anaconda3/lib/python3.7/site-packages/sqlalchemy/engine/strategies.py", line 114, in connect
    return dialect.connect(*cargs, **cparams)
  File "/Users/dankmank/anaconda3/lib/python3.7/site-packages/sqlalchemy/engine/default.py", line 490, in connect
    return self.dbapi.connect(*cargs, **cparams)
  File "/Users/dankmank/anaconda3/lib/python3.7/site-packages/psycopg2/__init__.py", line 127, in connect
    conn = _connect(dsn, connection_factory=connection_factory, **kwasync)
psycopg2.OperationalError: FATAL:  too many connections for role "kdscstklqmukmb"


The above exception was the direct cause of the following exception:

Traceback (most recent call last):
  File "/Users/dankmank/anaconda3/lib/python3.7/site-packages/gunicorn/arbiter.py", line 583, in spawn_worker
    worker.init_process()
  File "/Users/dankmank/anaconda3/lib/python3.7/site-packages/gunicorn/workers/base.py", line 129, in init_process
    self.load_wsgi()
  File "/Users/dankmank/anaconda3/lib/python3.7/site-packages/gunicorn/workers/base.py", line 138, in load_wsgi
    self.wsgi = self.app.wsgi()
  File "/Users/dankmank/anaconda3/lib/python3.7/site-packages/gunicorn/app/base.py", line 67, in wsgi
    self.callable = self.load()
  File "/Users/dankmank/anaconda3/lib/python3.7/site-packages/psiturk/experiment_server.py", line 48, in load
    return util.import_app("psiturk.experiment:app")
  File "/Users/dankmank/anaconda3/lib/python3.7/site-packages/gunicorn/util.py", line 350, in import_app
    __import__(module)
  File "/Users/dankmank/anaconda3/lib/python3.7/site-packages/psiturk/experiment.py", line 89, in <module>
    init_db()
  File "/Users/dankmank/anaconda3/lib/python3.7/site-packages/psiturk/db.py", line 37, in init_db
    Base.metadata.create_all(bind=engine)
  File "/Users/dankmank/anaconda3/lib/python3.7/site-packages/sqlalchemy/sql/schema.py", line 4465, in create_all
    ddl.SchemaGenerator, self, checkfirst=checkfirst, tables=tables
  File "/Users/dankmank/anaconda3/lib/python3.7/site-packages/sqlalchemy/engine/base.py", line 2103, in _run_visitor
    with self._optional_conn_ctx_manager(connection) as conn:
  File "/Users/dankmank/anaconda3/lib/python3.7/contextlib.py", line 112, in __enter__
    return next(self.gen)
  File "/Users/dankmank/anaconda3/lib/python3.7/site-packages/sqlalchemy/engine/base.py", line 2095, in _optional_conn_ctx_manager
    with self._contextual_connect() as conn:
  File "/Users/dankmank/anaconda3/lib/python3.7/site-packages/sqlalchemy/engine/base.py", line 2311, in _contextual_connect
    self._wrap_pool_connect(self.pool.connect, None),
  File "/Users/dankmank/anaconda3/lib/python3.7/site-packages/sqlalchemy/engine/base.py", line 2349, in _wrap_pool_connect
    e, dialect, self
  File "/Users/dankmank/anaconda3/lib/python3.7/site-packages/sqlalchemy/engine/base.py", line 1591, in _handle_dbapi_exception_noconnection
    sqlalchemy_exception, with_traceback=exc_info[2], from_=e
  File "/Users/dankmank/anaconda3/lib/python3.7/site-packages/sqlalchemy/util/compat.py", line 178, in raise_
    raise exception
  File "/Users/dankmank/anaconda3/lib/python3.7/site-packages/sqlalchemy/engine/base.py", line 2345, in _wrap_pool_connect
    return fn()
  File "/Users/dankmank/anaconda3/lib/python3.7/site-packages/sqlalchemy/pool/base.py", line 364, in connect
    return _ConnectionFairy._checkout(self)
  File "/Users/dankmank/anaconda3/lib/python3.7/site-packages/sqlalchemy/pool/base.py", line 778, in _checkout
    fairy = _ConnectionRecord.checkout(pool)
  File "/Users/dankmank/anaconda3/lib/python3.7/site-packages/sqlalchemy/pool/base.py", line 495, in checkout
    rec = pool._do_get()
  File "/Users/dankmank/anaconda3/lib/python3.7/site-packages/sqlalchemy/pool/impl.py", line 140, in _do_get
    self._dec_overflow()
  File "/Users/dankmank/anaconda3/lib/python3.7/site-packages/sqlalchemy/util/langhelpers.py", line 69, in __exit__
    exc_value, with_traceback=exc_tb,
  File "/Users/dankmank/anaconda3/lib/python3.7/site-packages/sqlalchemy/util/compat.py", line 178, in raise_
    raise exception
  File "/Users/dankmank/anaconda3/lib/python3.7/site-packages/sqlalchemy/pool/impl.py", line 137, in _do_get
    return self._create_connection()
  File "/Users/dankmank/anaconda3/lib/python3.7/site-packages/sqlalchemy/pool/base.py", line 309, in _create_connection
    return _ConnectionRecord(self)
  File "/Users/dankmank/anaconda3/lib/python3.7/site-packages/sqlalchemy/pool/base.py", line 440, in __init__
    self.__connect(first_connect_check=True)
  File "/Users/dankmank/anaconda3/lib/python3.7/site-packages/sqlalchemy/pool/base.py", line 661, in __connect
    pool.logger.debug("Error on connect(): %s", e)
  File "/Users/dankmank/anaconda3/lib/python3.7/site-packages/sqlalchemy/util/langhelpers.py", line 69, in __exit__
    exc_value, with_traceback=exc_tb,
  File "/Users/dankmank/anaconda3/lib/python3.7/site-packages/sqlalchemy/util/compat.py", line 178, in raise_
    raise exception
  File "/Users/dankmank/anaconda3/lib/python3.7/site-packages/sqlalchemy/pool/base.py", line 656, in __connect
    connection = pool._invoke_creator(self)
  File "/Users/dankmank/anaconda3/lib/python3.7/site-packages/sqlalchemy/engine/strategies.py", line 114, in connect
    return dialect.connect(*cargs, **cparams)
  File "/Users/dankmank/anaconda3/lib/python3.7/site-packages/sqlalchemy/engine/default.py", line 490, in connect
    return self.dbapi.connect(*cargs, **cparams)
  File "/Users/dankmank/anaconda3/lib/python3.7/site-packages/psycopg2/__init__.py", line 127, in connect
    conn = _connect(dsn, connection_factory=connection_factory, **kwasync)
sqlalchemy.exc.OperationalError: (psycopg2.OperationalError) FATAL:  too many connections for role "kdscstklqmukmb"

(Background on this error at: http://sqlalche.me/e/e3q8)
[2020-07-07 17:15:30 -0700] [19143] [ERROR] Exception in worker process
Traceback (most recent call last):
  File "/Users/dankmank/anaconda3/lib/python3.7/site-packages/sqlalchemy/engine/base.py", line 2345, in _wrap_pool_connect
    return fn()
  File "/Users/dankmank/anaconda3/lib/python3.7/site-packages/sqlalchemy/pool/base.py", line 364, in connect
    return _ConnectionFairy._checkout(self)
  File "/Users/dankmank/anaconda3/lib/python3.7/site-packages/sqlalchemy/pool/base.py", line 778, in _checkout
    fairy = _ConnectionRecord.checkout(pool)
  File "/Users/dankmank/anaconda3/lib/python3.7/site-packages/sqlalchemy/pool/base.py", line 495, in checkout
    rec = pool._do_get()
  File "/Users/dankmank/anaconda3/lib/python3.7/site-packages/sqlalchemy/pool/impl.py", line 140, in _do_get
    self._dec_overflow()
  File "/Users/dankmank/anaconda3/lib/python3.7/site-packages/sqlalchemy/util/langhelpers.py", line 69, in __exit__
    exc_value, with_traceback=exc_tb,
  File "/Users/dankmank/anaconda3/lib/python3.7/site-packages/sqlalchemy/util/compat.py", line 178, in raise_
    raise exception
  File "/Users/dankmank/anaconda3/lib/python3.7/site-packages/sqlalchemy/pool/impl.py", line 137, in _do_get
    return self._create_connection()
  File "/Users/dankmank/anaconda3/lib/python3.7/site-packages/sqlalchemy/pool/base.py", line 309, in _create_connection
    return _ConnectionRecord(self)
  File "/Users/dankmank/anaconda3/lib/python3.7/site-packages/sqlalchemy/pool/base.py", line 440, in __init__
    self.__connect(first_connect_check=True)
  File "/Users/dankmank/anaconda3/lib/python3.7/site-packages/sqlalchemy/pool/base.py", line 661, in __connect
    pool.logger.debug("Error on connect(): %s", e)
  File "/Users/dankmank/anaconda3/lib/python3.7/site-packages/sqlalchemy/util/langhelpers.py", line 69, in __exit__
    exc_value, with_traceback=exc_tb,
  File "/Users/dankmank/anaconda3/lib/python3.7/site-packages/sqlalchemy/util/compat.py", line 178, in raise_
    raise exception
  File "/Users/dankmank/anaconda3/lib/python3.7/site-packages/sqlalchemy/pool/base.py", line 656, in __connect
    connection = pool._invoke_creator(self)
  File "/Users/dankmank/anaconda3/lib/python3.7/site-packages/sqlalchemy/engine/strategies.py", line 114, in connect
    return dialect.connect(*cargs, **cparams)
  File "/Users/dankmank/anaconda3/lib/python3.7/site-packages/sqlalchemy/engine/default.py", line 490, in connect
    return self.dbapi.connect(*cargs, **cparams)
  File "/Users/dankmank/anaconda3/lib/python3.7/site-packages/psycopg2/__init__.py", line 127, in connect
    conn = _connect(dsn, connection_factory=connection_factory, **kwasync)
psycopg2.OperationalError: FATAL:  too many connections for role "kdscstklqmukmb"


The above exception was the direct cause of the following exception:

Traceback (most recent call last):
  File "/Users/dankmank/anaconda3/lib/python3.7/site-packages/gunicorn/arbiter.py", line 583, in spawn_worker
    worker.init_process()
  File "/Users/dankmank/anaconda3/lib/python3.7/site-packages/gunicorn/workers/base.py", line 129, in init_process
    self.load_wsgi()
  File "/Users/dankmank/anaconda3/lib/python3.7/site-packages/gunicorn/workers/base.py", line 138, in load_wsgi
    self.wsgi = self.app.wsgi()
  File "/Users/dankmank/anaconda3/lib/python3.7/site-packages/gunicorn/app/base.py", line 67, in wsgi
    self.callable = self.load()
  File "/Users/dankmank/anaconda3/lib/python3.7/site-packages/psiturk/experiment_server.py", line 48, in load
    return util.import_app("psiturk.experiment:app")
  File "/Users/dankmank/anaconda3/lib/python3.7/site-packages/gunicorn/util.py", line 350, in import_app
    __import__(module)
  File "/Users/dankmank/anaconda3/lib/python3.7/site-packages/psiturk/experiment.py", line 89, in <module>
    init_db()
  File "/Users/dankmank/anaconda3/lib/python3.7/site-packages/psiturk/db.py", line 37, in init_db
    Base.metadata.create_all(bind=engine)
  File "/Users/dankmank/anaconda3/lib/python3.7/site-packages/sqlalchemy/sql/schema.py", line 4465, in create_all
    ddl.SchemaGenerator, self, checkfirst=checkfirst, tables=tables
  File "/Users/dankmank/anaconda3/lib/python3.7/site-packages/sqlalchemy/engine/base.py", line 2103, in _run_visitor
    with self._optional_conn_ctx_manager(connection) as conn:
  File "/Users/dankmank/anaconda3/lib/python3.7/contextlib.py", line 112, in __enter__
    return next(self.gen)
  File "/Users/dankmank/anaconda3/lib/python3.7/site-packages/sqlalchemy/engine/base.py", line 2095, in _optional_conn_ctx_manager
    with self._contextual_connect() as conn:
  File "/Users/dankmank/anaconda3/lib/python3.7/site-packages/sqlalchemy/engine/base.py", line 2311, in _contextual_connect
    self._wrap_pool_connect(self.pool.connect, None),
  File "/Users/dankmank/anaconda3/lib/python3.7/site-packages/sqlalchemy/engine/base.py", line 2349, in _wrap_pool_connect
    e, dialect, self
  File "/Users/dankmank/anaconda3/lib/python3.7/site-packages/sqlalchemy/engine/base.py", line 1591, in _handle_dbapi_exception_noconnection
    sqlalchemy_exception, with_traceback=exc_info[2], from_=e
  File "/Users/dankmank/anaconda3/lib/python3.7/site-packages/sqlalchemy/util/compat.py", line 178, in raise_
    raise exception
  File "/Users/dankmank/anaconda3/lib/python3.7/site-packages/sqlalchemy/engine/base.py", line 2345, in _wrap_pool_connect
    return fn()
  File "/Users/dankmank/anaconda3/lib/python3.7/site-packages/sqlalchemy/pool/base.py", line 364, in connect
    return _ConnectionFairy._checkout(self)
  File "/Users/dankmank/anaconda3/lib/python3.7/site-packages/sqlalchemy/pool/base.py", line 778, in _checkout
    fairy = _ConnectionRecord.checkout(pool)
  File "/Users/dankmank/anaconda3/lib/python3.7/site-packages/sqlalchemy/pool/base.py", line 495, in checkout
    rec = pool._do_get()
  File "/Users/dankmank/anaconda3/lib/python3.7/site-packages/sqlalchemy/pool/impl.py", line 140, in _do_get
    self._dec_overflow()
  File "/Users/dankmank/anaconda3/lib/python3.7/site-packages/sqlalchemy/util/langhelpers.py", line 69, in __exit__
    exc_value, with_traceback=exc_tb,
  File "/Users/dankmank/anaconda3/lib/python3.7/site-packages/sqlalchemy/util/compat.py", line 178, in raise_
    raise exception
  File "/Users/dankmank/anaconda3/lib/python3.7/site-packages/sqlalchemy/pool/impl.py", line 137, in _do_get
    return self._create_connection()
  File "/Users/dankmank/anaconda3/lib/python3.7/site-packages/sqlalchemy/pool/base.py", line 309, in _create_connection
    return _ConnectionRecord(self)
  File "/Users/dankmank/anaconda3/lib/python3.7/site-packages/sqlalchemy/pool/base.py", line 440, in __init__
    self.__connect(first_connect_check=True)
  File "/Users/dankmank/anaconda3/lib/python3.7/site-packages/sqlalchemy/pool/base.py", line 661, in __connect
    pool.logger.debug("Error on connect(): %s", e)
  File "/Users/dankmank/anaconda3/lib/python3.7/site-packages/sqlalchemy/util/langhelpers.py", line 69, in __exit__
    exc_value, with_traceback=exc_tb,
  File "/Users/dankmank/anaconda3/lib/python3.7/site-packages/sqlalchemy/util/compat.py", line 178, in raise_
    raise exception
  File "/Users/dankmank/anaconda3/lib/python3.7/site-packages/sqlalchemy/pool/base.py", line 656, in __connect
    connection = pool._invoke_creator(self)
  File "/Users/dankmank/anaconda3/lib/python3.7/site-packages/sqlalchemy/engine/strategies.py", line 114, in connect
    return dialect.connect(*cargs, **cparams)
  File "/Users/dankmank/anaconda3/lib/python3.7/site-packages/sqlalchemy/engine/default.py", line 490, in connect
    return self.dbapi.connect(*cargs, **cparams)
  File "/Users/dankmank/anaconda3/lib/python3.7/site-packages/psycopg2/__init__.py", line 127, in connect
    conn = _connect(dsn, connection_factory=connection_factory, **kwasync)
sqlalchemy.exc.OperationalError: (psycopg2.OperationalError) FATAL:  too many connections for role "kdscstklqmukmb"

(Background on this error at: http://sqlalche.me/e/e3q8)
[2020-07-07 17:15:30 -0700] [19142] [ERROR] Exception in worker process
Traceback (most recent call last):
  File "/Users/dankmank/anaconda3/lib/python3.7/site-packages/sqlalchemy/engine/base.py", line 2345, in _wrap_pool_connect
    return fn()
  File "/Users/dankmank/anaconda3/lib/python3.7/site-packages/sqlalchemy/pool/base.py", line 364, in connect
    return _ConnectionFairy._checkout(self)
  File "/Users/dankmank/anaconda3/lib/python3.7/site-packages/sqlalchemy/pool/base.py", line 778, in _checkout
    fairy = _ConnectionRecord.checkout(pool)
  File "/Users/dankmank/anaconda3/lib/python3.7/site-packages/sqlalchemy/pool/base.py", line 495, in checkout
    rec = pool._do_get()
  File "/Users/dankmank/anaconda3/lib/python3.7/site-packages/sqlalchemy/pool/impl.py", line 140, in _do_get
    self._dec_overflow()
  File "/Users/dankmank/anaconda3/lib/python3.7/site-packages/sqlalchemy/util/langhelpers.py", line 69, in __exit__
    exc_value, with_traceback=exc_tb,
  File "/Users/dankmank/anaconda3/lib/python3.7/site-packages/sqlalchemy/util/compat.py", line 178, in raise_
    raise exception
  File "/Users/dankmank/anaconda3/lib/python3.7/site-packages/sqlalchemy/pool/impl.py", line 137, in _do_get
    return self._create_connection()
  File "/Users/dankmank/anaconda3/lib/python3.7/site-packages/sqlalchemy/pool/base.py", line 309, in _create_connection
    return _ConnectionRecord(self)
  File "/Users/dankmank/anaconda3/lib/python3.7/site-packages/sqlalchemy/pool/base.py", line 440, in __init__
    self.__connect(first_connect_check=True)
  File "/Users/dankmank/anaconda3/lib/python3.7/site-packages/sqlalchemy/pool/base.py", line 661, in __connect
    pool.logger.debug("Error on connect(): %s", e)
  File "/Users/dankmank/anaconda3/lib/python3.7/site-packages/sqlalchemy/util/langhelpers.py", line 69, in __exit__
    exc_value, with_traceback=exc_tb,
  File "/Users/dankmank/anaconda3/lib/python3.7/site-packages/sqlalchemy/util/compat.py", line 178, in raise_
    raise exception
  File "/Users/dankmank/anaconda3/lib/python3.7/site-packages/sqlalchemy/pool/base.py", line 656, in __connect
    connection = pool._invoke_creator(self)
  File "/Users/dankmank/anaconda3/lib/python3.7/site-packages/sqlalchemy/engine/strategies.py", line 114, in connect
    return dialect.connect(*cargs, **cparams)
  File "/Users/dankmank/anaconda3/lib/python3.7/site-packages/sqlalchemy/engine/default.py", line 490, in connect
    return self.dbapi.connect(*cargs, **cparams)
  File "/Users/dankmank/anaconda3/lib/python3.7/site-packages/psycopg2/__init__.py", line 127, in connect
    conn = _connect(dsn, connection_factory=connection_factory, **kwasync)
psycopg2.OperationalError: FATAL:  too many connections for role "kdscstklqmukmb"


The above exception was the direct cause of the following exception:

Traceback (most recent call last):
  File "/Users/dankmank/anaconda3/lib/python3.7/site-packages/gunicorn/arbiter.py", line 583, in spawn_worker
    worker.init_process()
  File "/Users/dankmank/anaconda3/lib/python3.7/site-packages/gunicorn/workers/base.py", line 129, in init_process
    self.load_wsgi()
  File "/Users/dankmank/anaconda3/lib/python3.7/site-packages/gunicorn/workers/base.py", line 138, in load_wsgi
    self.wsgi = self.app.wsgi()
  File "/Users/dankmank/anaconda3/lib/python3.7/site-packages/gunicorn/app/base.py", line 67, in wsgi
    self.callable = self.load()
  File "/Users/dankmank/anaconda3/lib/python3.7/site-packages/psiturk/experiment_server.py", line 48, in load
    return util.import_app("psiturk.experiment:app")
  File "/Users/dankmank/anaconda3/lib/python3.7/site-packages/gunicorn/util.py", line 350, in import_app
    __import__(module)
  File "/Users/dankmank/anaconda3/lib/python3.7/site-packages/psiturk/experiment.py", line 89, in <module>
    init_db()
  File "/Users/dankmank/anaconda3/lib/python3.7/site-packages/psiturk/db.py", line 37, in init_db
    Base.metadata.create_all(bind=engine)
  File "/Users/dankmank/anaconda3/lib/python3.7/site-packages/sqlalchemy/sql/schema.py", line 4465, in create_all
    ddl.SchemaGenerator, self, checkfirst=checkfirst, tables=tables
  File "/Users/dankmank/anaconda3/lib/python3.7/site-packages/sqlalchemy/engine/base.py", line 2103, in _run_visitor
    with self._optional_conn_ctx_manager(connection) as conn:
  File "/Users/dankmank/anaconda3/lib/python3.7/contextlib.py", line 112, in __enter__
    return next(self.gen)
  File "/Users/dankmank/anaconda3/lib/python3.7/site-packages/sqlalchemy/engine/base.py", line 2095, in _optional_conn_ctx_manager
    with self._contextual_connect() as conn:
  File "/Users/dankmank/anaconda3/lib/python3.7/site-packages/sqlalchemy/engine/base.py", line 2311, in _contextual_connect
    self._wrap_pool_connect(self.pool.connect, None),
  File "/Users/dankmank/anaconda3/lib/python3.7/site-packages/sqlalchemy/engine/base.py", line 2349, in _wrap_pool_connect
    e, dialect, self
  File "/Users/dankmank/anaconda3/lib/python3.7/site-packages/sqlalchemy/engine/base.py", line 1591, in _handle_dbapi_exception_noconnection
    sqlalchemy_exception, with_traceback=exc_info[2], from_=e
  File "/Users/dankmank/anaconda3/lib/python3.7/site-packages/sqlalchemy/util/compat.py", line 178, in raise_
    raise exception
  File "/Users/dankmank/anaconda3/lib/python3.7/site-packages/sqlalchemy/engine/base.py", line 2345, in _wrap_pool_connect
    return fn()
  File "/Users/dankmank/anaconda3/lib/python3.7/site-packages/sqlalchemy/pool/base.py", line 364, in connect
    return _ConnectionFairy._checkout(self)
  File "/Users/dankmank/anaconda3/lib/python3.7/site-packages/sqlalchemy/pool/base.py", line 778, in _checkout
    fairy = _ConnectionRecord.checkout(pool)
  File "/Users/dankmank/anaconda3/lib/python3.7/site-packages/sqlalchemy/pool/base.py", line 495, in checkout
    rec = pool._do_get()
  File "/Users/dankmank/anaconda3/lib/python3.7/site-packages/sqlalchemy/pool/impl.py", line 140, in _do_get
    self._dec_overflow()
  File "/Users/dankmank/anaconda3/lib/python3.7/site-packages/sqlalchemy/util/langhelpers.py", line 69, in __exit__
    exc_value, with_traceback=exc_tb,
  File "/Users/dankmank/anaconda3/lib/python3.7/site-packages/sqlalchemy/util/compat.py", line 178, in raise_
    raise exception
  File "/Users/dankmank/anaconda3/lib/python3.7/site-packages/sqlalchemy/pool/impl.py", line 137, in _do_get
    return self._create_connection()
  File "/Users/dankmank/anaconda3/lib/python3.7/site-packages/sqlalchemy/pool/base.py", line 309, in _create_connection
    return _ConnectionRecord(self)
  File "/Users/dankmank/anaconda3/lib/python3.7/site-packages/sqlalchemy/pool/base.py", line 440, in __init__
    self.__connect(first_connect_check=True)
  File "/Users/dankmank/anaconda3/lib/python3.7/site-packages/sqlalchemy/pool/base.py", line 661, in __connect
    pool.logger.debug("Error on connect(): %s", e)
  File "/Users/dankmank/anaconda3/lib/python3.7/site-packages/sqlalchemy/util/langhelpers.py", line 69, in __exit__
    exc_value, with_traceback=exc_tb,
  File "/Users/dankmank/anaconda3/lib/python3.7/site-packages/sqlalchemy/util/compat.py", line 178, in raise_
    raise exception
  File "/Users/dankmank/anaconda3/lib/python3.7/site-packages/sqlalchemy/pool/base.py", line 656, in __connect
    connection = pool._invoke_creator(self)
  File "/Users/dankmank/anaconda3/lib/python3.7/site-packages/sqlalchemy/engine/strategies.py", line 114, in connect
    return dialect.connect(*cargs, **cparams)
  File "/Users/dankmank/anaconda3/lib/python3.7/site-packages/sqlalchemy/engine/default.py", line 490, in connect
    return self.dbapi.connect(*cargs, **cparams)
  File "/Users/dankmank/anaconda3/lib/python3.7/site-packages/psycopg2/__init__.py", line 127, in connect
    conn = _connect(dsn, connection_factory=connection_factory, **kwasync)
sqlalchemy.exc.OperationalError: (psycopg2.OperationalError) FATAL:  too many connections for role "kdscstklqmukmb"

(Background on this error at: http://sqlalche.me/e/e3q8)
